Workbook
Name a: #REF!
Name a: #REF!
Name a: #REF!
Name a: #REF!
Name a: #REF!
Name a: #REF!
Name a: #REF!
Name a: #REF!
Name a: #REF!
Name a: #REF!
Name a: #REF!
Name a: #REF!
Name a: #REF!
Name a: #REF!
Name a: #REF!
Name a: #REF!
Name a: #REF!
Name aa: #REF!
Name aa: #REF!
Name aa: #REF!
Name aa: #REF!
Name aa: #REF!
Name aa: #REF!
Name aa: #REF!
Name aa: #REF!
Name aa: #REF!
Name aa: #REF!
Name aa: #REF!
Name aa: #REF!
Name aa: #REF!
Name aa: #REF!
Name aa: #REF!
Name aa: #REF!
Name aaaaa: #REF!
Name aaaaa: #REF!
Name aaaaa: #REF!
Name aaaaa: #REF!
Name aaaaa: #REF!
Name aaaaa: #REF!
Name aaaaa: #REF!
Name aaaaa: #REF!
Name aaaaa: #REF!
Name aaaaa: #REF!
Name aaaaa: #REF!
Name aaaaa: #REF!
Name aaaaa: #REF!
Name aaaaa: #REF!
Name aaaaa: #REF!
Name aaaaa: #REF!
Name auto: Empresas!#REF!
Name autoss: #REF!
Name BB: #REF!
Name BB: #REF!
Name ddd: Empresas!#REF!
Name ddd: Empresas!#REF!
Name ddd: Empresas!#REF!
Name ddd: Empresas!#REF!
Name ddd: Empresas!#REF!
Name ddd: Empresas!#REF!
Name ddd: Empresas!#REF!

Sheet Operacion
B1: FECHA | D1: 46278
B2: Unidad | C2: Q PERS | D2: Titulares | E2: Suplentes | G2: Trabajo 1 | M2: Q PERS | N2: Titulares | O2: Suplentes | Q2: Trabajo 2 | W2: Q PERS | X2: Titulares | Y2: Suplentes | AA2: Trabajo 3 | AG2: Q PERS | AH2: Titulares | AI2: Suplentes | AK2: Trabajo 4
D3: Personal | E3: Equipos | F3: Personal | G3: Seleccione Empresa | I3: OT | J3: 0 | K3: Remito | L3: 0 | N3: Personal | O3: Equipos | P3: Personal | Q3: Seleccione Empresa | S3: OT | T3: 0 | U3: Remito | V3: 0 | X3: Personal | Y3: Equipos | Z3: Personal | AA3: Seleccione Empresa | AC3: OT | AD3: 0 | AE3: Remito | AF3: 0 | AH3: Personal | AI3: Equipos | AJ3: Personal | AK3: Seleccione Empresa | AM3: OT | AN3: 0 | AO3: Remito | AP3: 0
B4: GDU100 | E4: GDU000 | F4: Seleccione Chofer | G4: Cliente: | K4: Hora de Salida | N4: Seleccione Chofer | O4: GDU000 | P4: Seleccione Chofer | Q4: Cliente: | U4: Hora de Salida | X4: Seleccione Chofer | Y4: GDU000 | Z4: Seleccione Chofer | AA4: Cliente: | AE4: Hora de Salida | AH4: Seleccione Chofer | AI4: GDU000 | AJ4: Seleccione Chofer | AK4: Cliente: | AO4: Hora de Salida
B5: =VLOOKUP(B4,tablaequipo,4) -> Camion | E5: GDU000 | F5: Selección Acompanante | G5: Lugar Carga | N5: Selección Acompanante | O5: GDU000 | P5: Selección Acompanante | Q5: Lugar Carga | X5: Selección Acompanante | Y5: GDU000 | Z5: Selección Acompanante | AA5: Lugar Carga | AH5: Selección Acompanante | AI5: GDU000 | AJ5: Selección Acompanante | AK5: Lugar Carga
B6: =VLOOKUP(B4,tablaequipo,6) -> KIA | E6: GDU000 | F6: Selección Acompanante | G6: Contacto | K6: Telefono | N6: Selección Acompanante | O6: GDU000 | P6: Selección Acompanante | Q6: Contacto | U6: Telefono | X6: Selección Acompanante | Y6: GDU000 | Z6: Selección Acompanante | AA6: Contacto | AE6: Telefono | AH6: Selección Acompanante | AI6: GDU000 | AJ6: Selección Acompanante | AK6: Contacto | AO6: Telefono
B7: =VLOOKUP(B4,tablaequipo,7) -> K2500 | E7: GDU000 | F7: Selección Acompanante | G7: Lugar Descarga | N7: Selección Acompanante | O7: GDU000 | P7: Selección Acompanante | Q7: Lugar Descarga | X7: Selección Acompanante | Y7: GDU000 | Z7: Selección Acompanante | AA7: Lugar Descarga | AH7: Selección Acompanante | AI7: GDU000 | AJ7: Selección Acompanante | AK7: Lugar Descarga
B8: =VLOOKUP(B4,tablaequipo,8) -> ONT 594 | E8: GDU000 | F8: Guardia | G8: Contacto | K8: Telefono | N8: Selección Acompanante | O8: GDU000 | P8: Guardia | Q8: Contacto | U8: Telefono | X8: Selección Acompanante | Y8: GDU000 | Z8: Guardia | AA8: Contacto | AE8: Telefono | AH8: Selección Acompanante | AI8: GDU000 | AJ8: Guardia | AK8: Contacto | AO8: Telefono
B9: 0 | E9: GDU000 | F9: Seleccione Chofer | G9: Verificador | H9: Seleccione Verificador | J9: Operador | K9: Selección Operador | N9: Selección Acompanante | O9: GDU000 | P9: Seleccione Chofer | Q9: Verificador | R9: Seleccione Verificador | T9: Operador | U9: Selección Operador | X9: Selección Acompanante | Y9: GDU000 | Z9: Seleccione Chofer | AA9: Verificador | AB9: Seleccione Verificador | AD9: Operador | AE9: Selección Operador | AH9: Selección Acompanante | AI9: GDU000 | AJ9: Seleccione Chofer | AK9: Verificador | AL9: Seleccione Verificador | AN9: Operador | AO9: Selección Operador
B10: =VLOOKUP(B9,tablapermiso,3) -> Seleccione Gestion | E10: GDU000 | F10: Selección Acompanante | G10: 0 | H10: =VLOOKUP(G10,tablaestado,3) -> Seleccione Estado | N10: Selección Acompanante | O10: GDU000 | P10: Selección Acompanante | Q10: 0 | R10: =VLOOKUP(Q10,tablaestado,3) -> Seleccione Estado | X10: Selección Acompanante | Y10: GDU000 | Z10: Selección Acompanante | AA10: 0 | AB10: =VLOOKUP(AA10,tablaestado,3) -> Seleccione Estado | AH10: Selección Acompanante | AI10: GDU000 | AJ10: Selección Acompanante | AK10: 0 | AL10: =VLOOKUP(AK10,tablaestado,3) -> Seleccione Estado
B11: Unidad | C11: Q PERS | D11: Titulares | E11: Suplentes | G11: Trabajo 1 | M11: Q PERS | N11: Titulares | O11: Suplentes | Q11: Trabajo 2 | W11: Q PERS | X11: Titulares | Y11: Suplentes | AA11: Trabajo 3 | AG11: Q PERS | AH11: Titulares | AI11: Suplentes | AK11: Trabajo 4
D12: Personal | E12: Equipos | F12: Personal | G12: Seleccione Empresa | I12: OT | J12: 0 | K12: Remito | L12: 0 | N12: Personal | O12: Equipos | P12: Personal | Q12: Seleccione Empresa | S12: OT | T12: 0 | U12: Remito | V12: 0 | X12: Personal | Y12: Equipos | Z12: Personal | AA12: Seleccione Empresa | AC12: OT | AD12: 0 | AE12: Remito | AF12: 0 | AH12: Personal | AI12: Equipos | AJ12: Personal | AK12: Seleccione Empresa | AM12: OT | AN12: 0 | AO12: Remito | AP12: 0
B13: GDU101 | E13: GDU000 | F13: Seleccione Chofer | G13: Cliente: | K13: Hora de Salida | N13: Seleccione Chofer | O13: GDU000 | P13: Seleccione Chofer | Q13: Cliente: | U13: Hora de Salida | X13: Seleccione Chofer | Y13: GDU000 | Z13: Seleccione Chofer | AA13: Cliente: | AE13: Hora de Salida | AH13: Seleccione Chofer | AI13: GDU000 | AJ13: Seleccione Chofer | AK13: Cliente: | AO13: Hora de Salida
B14: =VLOOKUP(B13,tablaequipo,4) -> Camion | E14: GDU000 | F14: Selección Acompanante | G14: Lugar Carga | N14: Selección Acompanante | O14: GDU000 | P14: Selección Acompanante | Q14: Lugar Carga | X14: Selección Acompanante | Y14: GDU000 | Z14: Selección Acompanante | AA14: Lugar Carga | AH14: Selección Acompanante | AI14: GDU000 | AJ14: Selección Acompanante | AK14: Lugar Carga
B15: =VLOOKUP(B13,tablaequipo,6) -> HYUNDAI | E15: GDU000 | F15: Selección Acompanante | G15: Contacto | K15: Telefono | N15: Selección Acompanante | O15: GDU000 | P15: Selección Acompanante | Q15: Contacto | U15: Telefono | X15: Selección Acompanante | Y15: GDU000 | Z15: Selección Acompanante | AA15: Contacto | AE15: Telefono | AH15: Selección Acompanante | AI15: GDU000 | AJ15: Selección Acompanante | AK15: Contacto | AO15: Telefono
B16: =VLOOKUP(B13,tablaequipo,7) -> HD78 | E16: GDU000 | F16: Selección Acompanante | G16: Lugar Descarga | N16: Selección Acompanante | O16: GDU000 | P16: Selección Acompanante | Q16: Lugar Descarga | X16: Selección Acompanante | Y16: GDU000 | Z16: Selección Acompanante | AA16: Lugar Descarga | AH16: Selección Acompanante | AI16: GDU000 | AJ16: Selección Acompanante | AK16: Lugar Descarga
B17: =VLOOKUP(B13,tablaequipo,8) -> JLM 355 | E17: GDU000 | F17: Guardia | G17: Contacto | K17: Telefono | N17: Selección Acompanante | O17: GDU000 | P17: Guardia | Q17: Contacto | U17: Telefono | X17: Selección Acompanante | Y17: GDU000 | Z17: Guardia | AA17: Contacto | AE17: Telefono | AH17: Selección Acompanante | AI17: GDU000 | AJ17: Guardia | AK17: Contacto | AO17: Telefono
B18: 0 | E18: GDU000 | F18: Seleccione Chofer | G18: Verificador | H18: Seleccione Verificador | J18: Operador | K18: Selección Operador | N18: Selección Acompanante | O18: GDU000 | P18: Seleccione Chofer | Q18: Verificador | R18: Seleccione Verificador | T18: Operador | U18: Selección Operador | X18: Selección Acompanante | Y18: GDU000 | Z18: Seleccione Chofer | AA18: Verificador | AB18: Seleccione Verificador | AD18: Operador | AE18: Selección Operador | AH18: Selección Acompanante | AI18: GDU000 | AJ18: Seleccione Chofer | AK18: Verificador | AL18: Seleccione Verificador | AN18: Operador | AO18: Selección Operador
B19: =VLOOKUP(B18,tablapermiso,3) -> Seleccione Gestion | E19: GDU000 | F19: Selección Acompanante | G19: 0 | H19: =VLOOKUP(G19,tablaestado,3) -> Seleccione Estado | N19: Selección Acompanante | O19: GDU000 | P19: Selección Acompanante | Q19: 0 | R19: =VLOOKUP(Q19,tablaestado,3) -> Seleccione Estado | X19: Selección Acompanante | Y19: GDU000 | Z19: Selección Acompanante | AA19: 0 | AB19: =VLOOKUP(AA19,tablaestado,3) -> Seleccione Estado | AH19: Selección Acompanante | AI19: GDU000 | AJ19: Selección Acompanante | AK19: 0 | AL19: =VLOOKUP(AK19,tablaestado,3) -> Seleccione Estado
B20: Unidad | C20: Q PERS | D20: Titulares | E20: Suplentes | G20: Trabajo 1 | M20: Q PERS | N20: Titulares | O20: Suplentes | Q20: Trabajo 2 | W20: Q PERS | X20: Titulares | Y20: Suplentes | AA20: Trabajo 3 | AG20: Q PERS | AH20: Titulares | AI20: Suplentes | AK20: Trabajo 4
D21: Personal | E21: Equipos | F21: Personal | G21: Seleccione Empresa | I21: OT | J21: 0 | K21: Remito | L21: 0 | N21: Personal | O21: Equipos | P21: Personal | Q21: Seleccione Empresa | S21: OT | T21: 0 | U21: Remito | V21: 0 | X21: Personal | Y21: Equipos | Z21: Personal | AA21: Seleccione Empresa | AC21: OT | AD21: 0 | AE21: Remito | AF21: 0 | AH21: Personal | AI21: Equipos | AJ21: Personal | AK21: Seleccione Empresa | AM21: OT | AN21: 0 | AO21: Remito | AP21: 0
B22: GDU105 | D22: Seleccione Chofer | E22: GDU000 | F22: Seleccione Chofer | G22: Cliente: | K22: Hora de Salida | N22: Seleccione Chofer | O22: GDU000 | P22: Seleccione Chofer | Q22: Cliente: | U22: Hora de Salida | X22: Seleccione Chofer | Y22: GDU000 | Z22: Seleccione Chofer | AA22: Cliente: | AE22: Hora de Salida | AH22: Seleccione Chofer | AI22: GDU000 | AJ22: Seleccione Chofer | AK22: Cliente: | AO22: Hora de Salida
B23: =VLOOKUP(B22,tablaequipo,4) -> Camion | D23: Selección Acompanante | E23: GDU000 | F23: Selección Acompanante | G23: Lugar Carga | N23: Selección Acompanante | O23: GDU000 | P23: Selección Acompanante | Q23: Lugar Carga | X23: Selección Acompanante | Y23: GDU000 | Z23: Selección Acompanante | AA23: Lugar Carga | AH23: Selección Acompanante | AI23: GDU000 | AJ23: Selección Acompanante | AK23: Lugar Carga
B24: =VLOOKUP(B22,tablaequipo,6) -> VOLKSWAGEN | D24: Selección Acompanante | E24: GDU000 | F24: Selección Acompanante | G24: Contacto | K24: Telefono | N24: Selección Acompanante | O24: GDU000 | P24: Selección Acompanante | Q24: Contacto | U24: Telefono | X24: Selección Acompanante | Y24: GDU000 | Z24: Selección Acompanante | AA24: Contacto | AE24: Telefono | AH24: Selección Acompanante | AI24: GDU000 | AJ24: Selección Acompanante | AK24: Contacto | AO24: Telefono
B25: =VLOOKUP(B22,tablaequipo,7) -> 9150 | D25: Selección Acompanante | E25: GDU000 | F25: Selección Acompanante | G25: Lugar Descarga | N25: Selección Acompanante | O25: GDU000 | P25: Selección Acompanante | Q25: Lugar Descarga | X25: Selección Acompanante | Y25: GDU000 | Z25: Selección Acompanante | AA25: Lugar Descarga | AH25: Selección Acompanante | AI25: GDU000 | AJ25: Selección Acompanante | AK25: Lugar Descarga
B26: =VLOOKUP(B22,tablaequipo,8) -> MRF 907 | D26: Selección Acompanante | E26: GDU000 | F26: Guardia | G26: Contacto | K26: Telefono | N26: Selección Acompanante | O26: GDU000 | P26: Guardia | Q26: Contacto | U26: Telefono | X26: Selección Acompanante | Y26: GDU000 | Z26: Guardia | AA26: Contacto | AE26: Telefono | AH26: Selección Acompanante | AI26: GDU000 | AJ26: Guardia | AK26: Contacto | AO26: Telefono
B27: 0 | D27: Selección Acompanante | E27: GDU000 | F27: Seleccione Chofer | G27: Verificador | H27: Seleccione Verificador | J27: Operador | K27: Selección Operador | N27: Selección Acompanante | O27: GDU000 | P27: Seleccione Chofer | Q27: Verificador | R27: Seleccione Verificador | T27: Operador | U27: Selección Operador | X27: Selección Acompanante | Y27: GDU000 | Z27: Seleccione Chofer | AA27: Verificador | AB27: Seleccione Verificador | AD27: Operador | AE27: Selección Operador | AH27: Selección Acompanante | AI27: GDU000 | AJ27: Seleccione Chofer | AK27: Verificador | AL27: Seleccione Verificador | AN27: Operador | AO27: Selección Operador
B28: =VLOOKUP(B27,tablapermiso,3) -> Seleccione Gestion | D28: Selección Acompanante | E28: GDU000 | F28: Selección Acompanante | G28: 0 | H28: =VLOOKUP(G28,tablaestado,3) -> Seleccione Estado | N28: Selección Acompanante | O28: GDU000 | P28: Selección Acompanante | Q28: 0 | R28: =VLOOKUP(Q28,tablaestado,3) -> Seleccione Estado | X28: Selección Acompanante | Y28: GDU000 | Z28: Selección Acompanante | AA28: 0 | AB28: =VLOOKUP(AA28,tablaestado,3) -> Seleccione Estado | AH28: Selección Acompanante | AI28: GDU000 | AJ28: Selección Acompanante | AK28: 0 | AL28: =VLOOKUP(AK28,tablaestado,3) -> Seleccione Estado
B29: Unidad | C29: Q PERS | D29: Titulares | E29: Suplentes | G29: Trabajo 1 | M29: Q PERS | N29: Titulares | O29: Suplentes | Q29: Trabajo 2 | W29: Q PERS | X29: Titulares | Y29: Suplentes | AA29: Trabajo 3 | AG29: Q PERS | AH29: Titulares | AI29: Suplentes | AK29: Trabajo 4
D30: Personal | E30: Equipos | F30: Personal | G30: Seleccione Empresa | I30: OT | J30: 0 | K30: Remito | L30: 0 | N30: Personal | O30: Equipos | P30: Personal | Q30: Seleccione Empresa | S30: OT | T30: 0 | U30: Remito | V30: 0 | X30: Personal | Y30: Equipos | Z30: Personal | AA30: Seleccione Empresa | AC30: OT | AD30: 0 | AE30: Remito | AF30: 0 | AH30: Personal | AI30: Equipos | AJ30: Personal | AK30: Seleccione Empresa | AM30: OT | AN30: 0 | AO30: Remito | AP30: 0
B31: GDU106 | D31: Seleccione Chofer | E31: GDU000 | F31: Seleccione Chofer | G31: Cliente: | K31: Hora de Salida | N31: Seleccione Chofer | O31: GDU000 | P31: Seleccione Chofer | Q31: Cliente: | U31: Hora de Salida | X31: Seleccione Chofer | Y31: GDU000 | Z31: Seleccione Chofer | AA31: Cliente: | AE31: Hora de Salida | AH31: Seleccione Chofer | AI31: GDU000 | AJ31: Seleccione Chofer | AK31: Cliente: | AO31: Hora de Salida
B32: =VLOOKUP(B31,tablaequipo,4) -> Camion | D32: Selección Acompanante | E32: GDU000 | F32: Selección Acompanante | G32: Lugar Carga | N32: Selección Acompanante | O32: GDU000 | P32: Selección Acompanante | Q32: Lugar Carga | X32: Selección Acompanante | Y32: GDU000 | Z32: Selección Acompanante | AA32: Lugar Carga | AH32: Selección Acompanante | AI32: GDU000 | AJ32: Selección Acompanante | AK32: Lugar Carga
B33: =VLOOKUP(B31,tablaequipo,6) -> IVECO | D33: Selección Acompanante | E33: GDU000 | F33: Guardia | G33: Contacto | K33: Telefono | N33: Selección Acompanante | O33: GDU000 | P33: Guardia | Q33: Contacto | U33: Telefono | X33: Selección Acompanante | Y33: GDU000 | Z33: Guardia | AA33: Contacto | AE33: Telefono | AH33: Selección Acompanante | AI33: GDU000 | AJ33: Guardia | AK33: Contacto | AO33: Telefono
B34: =VLOOKUP(B31,tablaequipo,7) -> EURO 220 | D34: Selección Acompanante | E34: GDU000 | F34: Seleccione Chofer | G34: Lugar Descarga | N34: Selección Acompanante | O34: GDU000 | P34: Seleccione Chofer | Q34: Lugar Descarga | X34: Selección Acompanante | Y34: GDU000 | Z34: Seleccione Chofer | AA34: Lugar Descarga | AH34: Selección Acompanante | AI34: GDU000 | AJ34: Seleccione Chofer | AK34: Lugar Descarga
B35: =VLOOKUP(B31,tablaequipo,8) -> HOD 216 | D35: Selección Acompanante | E35: GDU000 | F35: Selección Acompanante | G35: Contacto | K35: Telefono | N35: Selección Acompanante | O35: GDU000 | P35: Selección Acompanante | Q35: Contacto | U35: Telefono | X35: Selección Acompanante | Y35: GDU000 | Z35: Selección Acompanante | AA35: Contacto | AE35: Telefono | AH35: Selección Acompanante | AI35: GDU000 | AJ35: Selección Acompanante | AK35: Contacto | AO35: Telefono
B36: 0 | D36: Selección Acompanante | E36: GDU000 | F36: GDU000 | G36: Verificador | H36: Seleccione Verificador | J36: Operador | K36: Selección Operador | N36: Selección Acompanante | O36: GDU000 | P36: GDU000 | Q36: Verificador | R36: Seleccione Verificador | T36: Operador | U36: Selección Operador | X36: Selección Acompanante | Y36: GDU000 | Z36: GDU000 | AA36: Verificador | AB36: Seleccione Verificador | AD36: Operador | AE36: Selección Operador | AH36: Selección Acompanante | AI36: GDU000 | AJ36: GDU000 | AK36: Verificador | AL36: Seleccione Verificador | AN36: Operador | AO36: Selección Operador
B37: =VLOOKUP(B36,tablapermiso,3) -> Seleccione Gestion | D37: Selección Acompanante | E37: GDU000 | F37: =VLOOKUP(F36,tablatractor,3) -> Seleccione Equipo | G37: 0 | H37: =VLOOKUP(G37,tablaestado,3) -> Seleccione Estado | N37: Selección Acompanante | O37: GDU000 | P37: =VLOOKUP(P36,tablatractor,3) -> Seleccione Equipo | Q37: 0 | R37: =VLOOKUP(Q37,tablaestado,3) -> Seleccione Estado | X37: Selección Acompanante | Y37: GDU000 | Z37: =VLOOKUP(Z36,tablatractor,3) -> Seleccione Equipo | AA37: 0 | AB37: =VLOOKUP(AA37,tablaestado,3) -> Seleccione Estado | AH37: Selección Acompanante | AI37: GDU000 | AJ37: =VLOOKUP(AJ36,tablatractor,3) -> Seleccione Equipo | AK37: 0 | AL37: =VLOOKUP(AK37,tablaestado,3) -> Seleccione Estado
B38: Unidad | C38: Q PERS | D38: Titulares | E38: Suplentes | G38: Trabajo 1 | M38: Q PERS | N38: Titulares | O38: Suplentes | Q38: Trabajo 2 | W38: Q PERS | X38: Titulares | Y38: Suplentes | AA38: Trabajo 3 | AG38: Q PERS | AH38: Titulares | AI38: Suplentes | AK38: Trabajo 4
D39: Personal | E39: Equipos | F39: Personal | G39: Seleccione Empresa | I39: OT | J39: 0 | K39: Remito | L39: 0 | N39: Personal | O39: Equipos | P39: Personal | Q39: Seleccione Empresa | S39: OT | T39: 0 | U39: Remito | V39: 0 | X39: Personal | Y39: Equipos | Z39: Personal | AA39: Seleccione Empresa | AC39: OT | AD39: 0 | AE39: Remito | AF39: 0 | AH39: Personal | AI39: Equipos | AJ39: Personal | AK39: Seleccione Empresa | AM39: OT | AN39: 0 | AO39: Remito | AP39: 0
B40: GDU110 | D40: Seleccione Chofer | E40: GDU000 | F40: Seleccione Chofer | G40: Cliente: | K40: Hora de Salida | N40: Seleccione Chofer | O40: GDU000 | P40: Seleccione Chofer | Q40: Cliente: | U40: Hora de Salida | X40: Seleccione Chofer | Y40: GDU000 | Z40: Seleccione Chofer | AA40: Cliente: | AE40: Hora de Salida | AH40: Seleccione Chofer | AI40: GDU000 | AJ40: Seleccione Chofer | AK40: Cliente: | AO40: Hora de Salida
...

Sheet Personal
A1: Codigo | B1: Apellido y Nombre | C1: Legajo | D1: Empresa | E1: Puesto | F1: DocumentoNumero
A2: GDE08 | B2: Andrada Pablo Manuel | D2: Hard Norton Rental SRL | E2: Chofer de Semi | F2: 30867116
A3: GDE05 | B3: Acosta Daniel Horacio | C3: GDL016 | D3: Universal Cranes | E3: Guinchero Especializado | F3: 22141224
A4: GDE04 | B4: Almaraz Dominguez Ricardo Juan | C4: GDL010 | D4: Movimientos Industriales Oeste | E4: Operador de Grua 60/90 TN | F4: 14673198
A5: GDE01 | B5: Arocha Sergio Anibal | C5: GDL001 | D5: Gruas Daniele SRL | E5: Operador de Grua 25/50 TN | F5: 16826947
A6: GDE03 | B6: Barreto Braian Jose | D6: West Group SH | E6: Operador de Grua 25/50 TN | F6: 38048913
A7: GDE04 | B7: Barrionuevo Claudio Andres | C7: GDL068 | D7: Movimientos Industriales Oeste | E7: Operador Aprendiz | F7: 29435006
A8: GDE04 | B8: Benitez Pablo Martin | C8: GDL081 | D8: Movimientos Industriales Oeste | E8: chofer de semirremolque | F8: 29822081
A9: GDE05 | B9: Bordones Requena Jordan Alexander | C9: GDL108 | D9: Universal Cranes | E9: Operador de Grua 175/250 TN | F9: 96288920
A10: GDE04 | B10: Cabrera Hugo Daniel | C10: GDL061 | D10: Movimientos Industriales Oeste | E10: Operador de Grua 25/50 TN | F10: 31835117
A11: GDE02 | B11: Caminatti Luis | C11: GDL007 | D11: Transportes Daniele | E11: Jefe de Cuadrilla Especializado | F11: 18073045
A12: GDE08 | B12: Campos Fernandez Jose Antonio | D12: Hard Norton Rental SRL | E12: Guinchero Ayudante | F12: 94340609
A13: GDE05 | B13: Cano Pablo Martin | C13: GDL047 | D13: Universal Cranes | E13: ADMINISTRATIVO | F13: 27899070
A14: GDE04 | B14: Cano Silvero Aldo Ruben | C14: GDL025 | D14: Movimientos Industriales Oeste | E14: Ayudante Aprendiz | F14: 34534374
A15: GDE03 | B15: Chavez Carlos Cesar | C15: GDL032 | D15: West Group SH | E15: Guinchero Ayudante | F15: 29578900
A16: GDE02 | B16: Ciocca Maria Florencia | C16: GDL097 | D16: Universal Cranes | E16: ADMINISTRATIVO | F16: 35380477
A17: GDE05 | B17: Cuevas Miguel Hector | C17: GDL017 | D17: Universal Cranes | E17: Verificador de Manualidades | F17: 12933549
A18: GDE01 | B18: Daniele Calvin Max | C18: GDL901 | D18: Grupo Daniele | F18: 93759575
A19: GDE01 | B19: Daniele Edgardo Rodolfo | C19: GDL900 | D19: Grupo Daniele | F19: 17196140
A20: GDE01 | B20: Daniele Jayson Edgar | C20: GDL902 | D20: Grupo Daniele | F20: 93759576
A21: GDE01 | B21: Daniele Nicolas Marvin | C21: GDL903 | D21: Grupo Daniele | F21: 93759578
A22: GDE01 | B22: De Felipe Hector Miguel | C22: GDL002 | D22: Gruas Daniele SRL | E22: Jefe de Cuadrilla | F22: 16750614
A23: GDE06 | B23: Fuentes Jorge Luis | C23: GDL052 | D23: Ehingen Service SRL | E23: MAESTRANZA | F23: 16032572
A24: GDE03 | B24: Gaitano Gerardo Ruben | C24: GDL050 | D24: West Group SH | E24: Chofer de Semi | F24: 29679535
A25: GDE04 | B25: Garay Esteban Horacio | C25: GDL012 | E25: Guinchero Ayudante | F25: 28451721
A26: GDE05 | B26: Giambroni Alberto Martin | C26: GDL019 | D26: Universal Cranes | E26: Jefe de Cuadrilla | F26: 30531012
A27: GDE103 | B27: Giambroni Sergio Leonardo | C27: GDL012 | D27: Movimientos Industriales Oeste | E27: Guinchero Ayudante | F27: 30436924
A28: GDE06 | B28: Gonzalez Molinas Juan Alberto | C28: GDL071 | D28: Ehingen Service SRL | E28: MECANICO | F28: 93066278
A29: GDE06 | B29: Graboviesky Javier Francisco | C29: GDL028 | D29: Ehingen Service SRL | E29: HERRERO | F29: 17335468
A30: GDE03 | B30: Hermoso Camacho Roberto Rafael | C30: GDL066 | D30: West Group SH | E30: Operador de Grua 25/50 TN | F30: 95839638
A31: GDE01 | B31: Ibañez Manuel | C31: GDL004 | D31: Gruas Daniele SRL | E31: Guinchero Ayudante | F31: 13662964
A32: GDE07 | B32: Jimenez Manuel Ernesto | C32: GDL078 | D32: Game Rental SRL | E32: Ayudante Aprendiz | F32: 95978100
A33: GDE05 | B33: Molina Rodrigo | C33: GDL058 | D33: Universal Cranes | E33: Chofer de Camion | F33: 42485087
A34: GDE03 | B34: Molina Dario Walter | C34: GDL029 | D34: West Group SH | E34: Ayudante | F34: 30794363
A35: GDE07 | B35: Montenegro Mariano Manuel | C35: GDL043 | D35: Game Rental SRL | E35: Operador de Grua 100/160 TN | F35: 32488934
A36: GDE07 | B36: Montenegro Matias Marcial | C36: GDL043 | D36: Game Rental SRL | E36: Ayudante Aprendiz | F36: 43999809
A37: GDE03 | B37: Nappi Juan Manuel | C37: GDL036 | D37: West Group SH | E37: Jefe de Cuadrilla Especializado | F37: 28131112
... A40: GDE07 | B40: Pereyra Machado Fernando | C40: GDL067 | D40: Game Rental SRL | E40: Chofer de Camion | F40: 93004858
A41: GDE01 | B41: Recines Alejandro | C41: GDL905 | D41: Grupo Daniele | F41: 33192185
A42: GDE08 | B42: Rios Franco Andres | D42: Hard Norton Rental SRL | F42: 43098545
...

Sheet GUARDIAS 
B3: Listado de Personal de Guardia
B5: FECHA | C5: =+Operacion!D1 -> 46278
B7: Guardia
B8: Chofer Grua | C8: Seleccione Chofer | D8: =VLOOKUP(C8,personal,5) -> 0
B9: Chofer Grua | C9: Seleccione Chofer | D9: =VLOOKUP(C9,personal,5) -> 0
B10: Chofer Camion | C10: Seleccione Chofer | D10: =VLOOKUP(C10,personal,5) -> 0
B11: Chofer Camion | C11: Seleccione Chofer | D11: =VLOOKUP(C11,personal,5) -> 0
B12: Ayudante | C12: Selección Acompanante | D12: =VLOOKUP(C12,personal,5) -> 0
B13: Ayudante | C13: Selección Acompanante | D13: =VLOOKUP(C13,personal,5) -> 0

Sheet Resumen Montera
A1: FECHA | B1: =+Operacion!D1 -> 46278
A3: Interno | B3: Tipo | C3: Marca | D3: Modelo | E3: Patente
A4: =+Operacion!B300 -> GDU800 | B4: =VLOOKUP(A4,tablaequipo,3) -> 0 | C4: =VLOOKUP(A4,tablaequipo,4) -> Camion | D4: =VLOOKUP(A4,tablaequipo,5) -> 0 | E4: =VLOOKUP(A4,tablaequipo,6) -> Alquiler Camion | G4: Lugar de Carga | H4: =+Operacion!H301 -> 0
G5: Contacto | H5: =+Operacion!H302 -> 0
B6: =+Operacion!D303 -> TRANS001 | C6: =+Operacion!D304 -> Transporte Montera | E6: Remito Transporte | G6: Telefono | H6: =+Operacion!L302 -> 0
B7: =+Operacion!D305 -> TIPO | C7: =+Operacion!D306 -> Seleccione Tipo | E7: =+Operacion!F304 -> 0
G8: Lugar de descarga | H8: =+Operacion!H303 -> 0
B9: Empresa | C9: =+Operacion!G299 -> Seleccione Empresa | E9: Remito GD | G9: Contacto | H9: =+Operacion!H304 -> 0
B10: Cliente | C10: =+Operacion!H300 -> 0 | E10: =+Operacion!L299 -> 0 | G10: Teléfono | H10: =+Operacion!L304 -> 0
B11: Hora de Carga | C11: =+Operacion!L300 -> 0
B13: Contacto GD | C13: =+Operacion!D300 -> Seleccione Contactos GD | G13: Descripcion de la Carga | H13: =+Operacion!H306 -> 0
B14: Teléfono | C14: =+Operacion!F300 -> 0
A15: Interno | B15: Tipo | C15: Marca | D15: Modelo | E15: Patente
A16: =+Operacion!B310 -> GDU801 | B16: =VLOOKUP(A16,tablaequipo,3) -> 0 | C16: =VLOOKUP(A16,tablaequipo,4) -> Camion | D16: =VLOOKUP(A16,tablaequipo,5) -> 0 | E16: =VLOOKUP(A16,tablaequipo,6) -> Alquiler Camion | G16: Lugar de Carga | H16: =+Operacion!H311 -> 0
G17: Contacto | H17: =+Operacion!H312 -> 0
B18: =+Operacion!D313 -> TRANS001 | C18: =+Operacion!D314 -> Transporte Montera | E18: Remito Transporte | G18: Teléfono | H18: =+Operacion!L312 -> 0
B19: =+Operacion!D315 -> TIPO | C19: =+Operacion!D316 -> Seleccione Tipo | E19: =+Operacion!F314 -> 0
G20: Lugar de descarga | H20: =+Operacion!H313 -> 0
B21: Empresa | C21: =+Operacion!G309 -> Seleccione Empresa | E21: Remito GD | G21: Contacto | H21: =+Operacion!H314 -> 0
B22: Cliente | C22: =+Operacion!H310 -> 0 | E22: =+Operacion!L309 -> 0 | G22: Teléfono | H22: =+Operacion!L314 -> 0
B23: Hora de Carga | C23: =+Operacion!L310 -> 0
B25: Contacto GD | C25: =+Operacion!D310 -> Seleccione Contactos GD | G25: Descripcion de la Carga | H25: =+Operacion!H316 -> 0
B26: Teléfono | C26: =+Operacion!F310 -> 0
A27: Interno | B27: Tipo | C27: Marca | D27: Modelo | E27: Patente
A28: =+Operacion!B320 -> GDU802 | B28: =VLOOKUP(A28,tablaequipo,3) -> 0 | C28: =VLOOKUP(A28,tablaequipo,4) -> Camion | D28: =VLOOKUP(A28,tablaequipo,5) -> 0 | E28: =VLOOKUP(A28,tablaequipo,6) -> Alquiler Camion | G28: Lugar de Carga | H28: =+Operacion!H321 -> 0
G29: Contacto | H29: =+Operacion!H322 -> 0
B30: =+Operacion!D323 -> TRANS001 | C30: =+Operacion!D324 -> Transporte Montera | E30: Remito Transporte | G30: Teléfono | H30: =+Operacion!L322 -> 0
B31: =+Operacion!D325 -> TIPO | C31: =+Operacion!D326 -> Seleccione Tipo | E31: =+Operacion!F324 -> 0
G32: Lugar de descarga | H32: =+Operacion!H323 -> 0
B33: Empresa | C33: =+Operacion!G319 -> Seleccione Empresa | E33: Remito GD | G33: Contacto | H33: =+Operacion!H324 -> 0
B34: Cliente | C34: =+Operacion!H320 -> 0 | E34: =+Operacion!L319 -> 0 | G34: Teléfono | H34: =+Operacion!L324 -> 0
B35: Hora de Carga | C35: =+Operacion!L320 -> 0
B37: Contacto GD | C37: =+Operacion!D320 -> Seleccione Contactos GD | G37: Descripcion de la Carga | H37: =+Operacion!H326 -> 0
B38: Teléfono | C38: =+Operacion!F320 -> 0
A39: Interno | B39: Tipo | C39: Marca | D39: Modelo | E39: Patente
A40: =+Operacion!B330 -> GDU803 | B40: =VLOOKUP(A40,tablaequipo,3) -> 0 | C40: =VLOOKUP(A40,tablaequipo,4) -> Camion | D40: =VLOOKUP(A40,tablaequipo,5) -> 0 | E40: =VLOOKUP(A40,tablaequipo,6) -> Alquiler Camion | G40: Lugar de Carga | H40: =+Operacion!H331 -> 0
G41: Contacto | H41: =+Operacion!H332 -> 0
B42: =+Operacion!D333 -> TRANS001 | C42: =+Operacion!D334 -> Transporte Montera | E42: Remito Transporte | G42: Teléfono | H42: =+Operacion!L332 -> 0
B43: =+Operacion!D335 -> TIPO | C43: =+Operacion!D336 -> Seleccione Tipo | E43: =+Operacion!F334 -> 0
G44: Lugar de descarga | H44: =+Operacion!H333 -> 0
...

Sheet Resumen Rivas
A1: FECHA | B1: =+Operacion!D1 -> 46278
A3: Interno | B3: Tipo | C3: Marca | D3: Modelo | E3: Patente
A4: =+Operacion!B360 -> GDU806 | B4: =VLOOKUP(A4,tablaequipo,3) -> 0 | C4: =VLOOKUP(A4,tablaequipo,4) -> Camion | D4: =VLOOKUP(A4,tablaequipo,5) -> 0 | E4: =VLOOKUP(A4,tablaequipo,6) -> Alquiler Camion | G4: Lugar de Carga | H4: =+Operacion!H361 -> 0
G5: Contacto | H5: =+Operacion!H362 -> 0
B6: =+Operacion!D363 -> TRANS002 | C6: =+Operacion!D364 -> Transporte Rivas | E6: Remito Transporte | G6: Telefono | H6: =+Operacion!L362 -> 0
B7: =+Operacion!D365 -> TIPO | C7: =+Operacion!D366 -> Seleccione Tipo | E7: =+Operacion!F364 -> 0
G8: Lugar de descarga | H8: =+Operacion!H363 -> 0
B9: Empresa | C9: =+Operacion!G359 -> Seleccione Empresa | E9: Remito GD | G9: Contacto | H9: =+Operacion!H364 -> 0
B10: Ciente | C10: =+Operacion!H360 -> 0 | E10: =+Operacion!L359 -> 0 | G10: Telefono | H10: =+Operacion!L364 -> 0
B11: Hora de Salida | C11: =+Operacion!L360 -> 0
B13: Contacto GD | C13: =+Operacion!D360 -> Seleccione Contactos GD | G13: Descripcion de la Carga | H13: =+Operacion!H366 -> 0
B14: Telefono | C14: =+Operacion!F360 -> 0
A15: Interno | B15: Tipo | C15: Marca | D15: Modelo | E15: Patente
A16: =+Operacion!B370 -> GDU807 | B16: =VLOOKUP(A16,tablaequipo,3) -> 0 | C16: =VLOOKUP(A16,tablaequipo,4) -> Camion | D16: =VLOOKUP(A16,tablaequipo,5) -> 0 | E16: =VLOOKUP(A16,tablaequipo,6) -> Alquiler Camion | G16: Lugar de Carga | H16: =+Operacion!H371 -> 0
G17: Contacto | H17: =+Operacion!H372 -> 0
B18: =+Operacion!D373 -> TRANS002 | C18: =+Operacion!D374 -> Transporte Rivas | E18: Remito Transporte | G18: Telefono | H18: =+Operacion!L372 -> 0
B19: =+Operacion!D375 -> TIPO | C19: =+Operacion!D376 -> Seleccione Tipo | E19: =+Operacion!F374 -> 0
G20: Lugar de descarga | H20: =+Operacion!H373 -> 0
B21: Empresa | C21: =+Operacion!G369 -> Seleccione Empresa | E21: Remito GD | G21: Contacto | H21: =+Operacion!H374 -> 0
B22: Ciente | C22: =+Operacion!H370 -> 0 | E22: =+Operacion!L369 -> 0 | G22: Telefono | H22: =+Operacion!L374 -> 0
B23: Hora de Salida | C23: =+Operacion!L370 -> 0
B25: Contacto GD | C25: =+Operacion!D370 -> Seleccione Contactos GD | G25: Descripcion de la Carga | H25: =+Operacion!H376 -> 0
B26: Telefono | C26: =+Operacion!F370 -> 0
A27: Interno | B27: Tipo | C27: Marca | D27: Modelo | E27: Patente
A28: =+Operacion!B380 -> GDU808 | B28: =VLOOKUP(A28,tablaequipo,3) -> 0 | C28: =VLOOKUP(A28,tablaequipo,4) -> Camion | D28: =VLOOKUP(A28,tablaequipo,5) -> 0 | E28: =VLOOKUP(A28,tablaequipo,6) -> Alquiler Camion | G28: Lugar de Carga | H28: =+Operacion!H381 -> 0
G29: Contacto | H29: =+Operacion!H382 -> 0
B30: =+Operacion!D383 -> TRANS002 | C30: =+Operacion!D384 -> Transporte Rivas | E30: Remito Transporte | G30: Telefono | H30: =+Operacion!L382 -> 0
B31: =+Operacion!D385 -> TIPO | C31: =+Operacion!D386 -> Seleccione Tipo | E31: =+Operacion!F384 -> 0
G32: Lugar de descarga | H32: =+Operacion!H383 -> 0
B33: Empresa | C33: =+Operacion!G379 -> Seleccione Empresa | E33: Remito GD | G33: Contacto | H33: =+Operacion!H384 -> 0
B34: Ciente | C34: =+Operacion!H380 -> 0 | E34: =+Operacion!L379 -> 0 | G34: Telefono | H34: =+Operacion!L384 -> 0
B35: Hora de Salida | C35: =+Operacion!L380 -> 0
B37: Contacto GD | C37: =+Operacion!D380 -> Seleccione Contactos GD | G37: Descripcion de la Carga | H37: =+Operacion!H386 -> 0
B38: Telefono | C38: =+Operacion!F380 -> 0

Sheet Resumen FMB
A1: FECHA | B1: =+Operacion!D1 -> 46278
A3: Interno | B3: Tipo | C3: Marca | D3: Modelo | E3: Patente
A4: =+Operacion!B390 -> GDU809 | B4: =VLOOKUP(A4,tablaequipo,3) -> 0 | C4: =VLOOKUP(A4,tablaequipo,4) -> Camion | D4: =VLOOKUP(A4,tablaequipo,5) -> 0 | E4: =VLOOKUP(A4,tablaequipo,6) -> Alquiler Camion | G4: Lugar de Carga | H4: =+Operacion!H391 -> 0
G5: Contacto | H5: =+Operacion!H392 -> 0
B6: =+Operacion!D393 -> TRANS003 | C6: =+Operacion!D394 -> Transporte FBM | E6: Remito Transporte | G6: Telefono | H6: =+Operacion!L392 -> 0
B7: =+Operacion!D395 -> TIPO | C7: =+Operacion!D396 -> Seleccione Tipo | E7: =+Operacion!F394 -> 0
G8: Lugar de descarga | H8: =+Operacion!H393 -> 0
B9: Empresa | C9: =+Operacion!G389 -> Seleccione Empresa | E9: Remito GD | G9: Contacto | H9: =+Operacion!H394 -> 0
B10: Ciente | C10: =+Operacion!H390 -> 0 | E10: =+Operacion!L389 -> 0 | G10: Telefono | H10: =+Operacion!L394 -> 0
B11: Hora de Salida | C11: =+Operacion!L390 -> 0
B13: Contacto GD | C13: =+Operacion!D390 -> Seleccione Contactos GD | G13: Descripcion de la Carga | H13: =+Operacion!H396 -> 0
B14: Telefono | C14: =+Operacion!F390 -> 0
A15: Interno | B15: Tipo | C15: Marca | D15: Modelo | E15: Patente
A16: =+Operacion!B400 -> GDU810 | B16: =VLOOKUP(A16,tablaequipo,3) -> 0 | C16: =VLOOKUP(A16,tablaequipo,4) -> Camion | D16: =VLOOKUP(A16,tablaequipo,5) -> 0 | E16: =VLOOKUP(A16,tablaequipo,6) -> Alquiler Camion | G16: Lugar de Carga | H16: =+Operacion!H401 -> 0
G17: Contacto | H17: =+Operacion!H402 -> 0
B18: =+Operacion!D403 -> TRANS003 | C18: =+Operacion!D404 -> Transporte FBM | E18: Remito Transporte | G18: Telefono | H18: =+Operacion!L402 -> 0
B19: =+Operacion!D405 -> TIPO | C19: =+Operacion!D406 -> Seleccione Tipo | E19: =+Operacion!F404 -> 0
G20: Lugar de descarga | H20: =+Operacion!H403 -> 0
B21: Empresa | C21: =+Operacion!G399 -> Seleccione Empresa | E21: Remito GD | G21: Contacto | H21: =+Operacion!H404 -> 0
B22: Ciente | C22: =+Operacion!H400 -> 0 | E22: =+Operacion!L399 -> 0 | G22: Telefono | H22: =+Operacion!L404 -> 0
B23: Hora de Salida | C23: =+Operacion!L400 -> 0
B25: Contacto GD | C25: =+Operacion!D400 -> Seleccione Contactos GD | G25: Descripcion de la Carga | H25: =+Operacion!H406 -> 0
B26: Telefono | C26: =+Operacion!F400 -> 0
A27: Interno | B27: Tipo | C27: Marca | D27: Modelo | E27: Patente
A28: =+Operacion!B410 -> GDU811 | B28: =VLOOKUP(A28,tablaequipo,3) -> 0 | C28: =VLOOKUP(A28,tablaequipo,4) -> Camion | D28: =VLOOKUP(A28,tablaequipo,5) -> 0 | E28: =VLOOKUP(A28,tablaequipo,6) -> Alquiler Camion | G28: Lugar de Carga | H28: =+Operacion!H411 -> 0
G29: Contacto | H29: =+Operacion!H412 -> 0
B30: =+Operacion!D413 -> TRANS003 | C30: =+Operacion!D414 -> Transporte FBM | E30: Remito Transporte | G30: Telefono | H30: =+Operacion!L412 -> 0
B31: =+Operacion!D415 -> TIPO | C31: =+Operacion!D416 -> Seleccione Tipo | E31: =+Operacion!F414 -> 0
G32: Lugar de descarga | H32: =+Operacion!H413 -> 0
B33: Empresa | C33: =+Operacion!G409 -> Seleccione Empresa | E33: Remito GD | G33: Contacto | H33: =+Operacion!H414 -> 0
B34: Ciente | C34: =+Operacion!H410 -> 0 | E34: =+Operacion!L409 -> 0 | G34: Telefono | H34: =+Operacion!L414 -> 0
B35: Hora de Salida | C35: =+Operacion!L410 -> 0
B37: Contacto GD | C37: =+Operacion!D410 -> Seleccione Contactos GD | G37: Descripcion de la Carga | H37: =+Operacion!H416 -> 0
B38: Telefono | C38: =+Operacion!F410 -> 0

Sheet 100-Kia
B2: Remito | E2: =+Operacion!G3 -> Seleccione Empresa | G2: Fecha: | H2: =+Operacion!D1 -> 46278
B4: Cliente | E4: =+Operacion!H4 -> 0 | G4: Hora de salida: | H4: =+Operacion!L4 -> 0
B6: Equipo: | E6: =+Operacion!B4 -> GDU100 | G6: Marca | H6: =VLOOKUP(E6,tablaequipo,6) -> KIA
E7: =VLOOKUP(E6,tablaequipo,3) -> 0 | G7: Modelo | H7: =VLOOKUP(E6,tablaequipo,7) -> K2500
G8: Patente | H8: =VLOOKUP(E6,tablaequipo,8) -> ONT 594
B10: Chofer: | E10: =+Operacion!D4 -> 0
B13: Acompañantes: | D13: 1 | E13: =+Operacion!D5 -> 0 | G13: 4 | H13: =+Operacion!D8 -> 0
D14: 2 | E14: =+Operacion!D6 -> 0 | G14: 5 | H14: =+Operacion!D9 -> 0
D15: 3 | E15: =+Operacion!D7 -> 0 | G15: 6 | H15: =+Operacion!D10 -> 0
B17: Verificador: | E17: =+Operacion!H9 -> Seleccione Verificador
B19: Operador | E19: =+Operacion!K9 -> Selección Operador
B21: Lugar de carga | E21: =+Operacion!H5 -> 0
B25: Contacto: | E25: =+Operacion!H6 -> 0
E26: =+Operacion!L6 -> 0
B28: Lugar de descarga | E28: =+Operacion!H7 -> 0
B32: Contacto: | E32: =+Operacion!H8 -> 0
E33: =+Operacion!L8 -> 0
B35: Observaciones

Sheet 101-Hyundai
B2: Remito | E2: =+Operacion!G12 -> Seleccione Empresa | G2: Fecha: | H2: =+Operacion!D1 -> 46278
B4: Cliente | E4: =+Operacion!H13 -> 0 | G4: Hora de salida: | H4: =+Operacion!L13 -> 0
B6: Equipo: | E6: =+Operacion!B13 -> GDU101 | G6: Marca | H6: =VLOOKUP(E6,tablaequipo,6) -> HYUNDAI
E7: =VLOOKUP(E6,tablaequipo,4) -> Camion | G7: Modelo | H7: =VLOOKUP(E6,tablaequipo,7) -> HD78
E8: =VLOOKUP(E6,tablaequipo,5) -> 0 | G8: Patente | H8: =VLOOKUP(E6,tablaequipo,8) -> JLM 355
B10: Chofer: | E10: =+Operacion!D13 -> 0
B13: Acompañantes: | D13: 1 | E13: =+Operacion!D14 -> 0 | G13: 4 | H13: =+Operacion!D17 -> 0
D14: 2 | E14: =+Operacion!D15 -> 0 | G14: 5 | H14: =+Operacion!D18 -> 0
D15: 3 | E15: =+Operacion!D16 -> 0 | G15: 6 | H15: =+Operacion!D19 -> 0
B17: Verificador: | E17: =+Operacion!H18 -> Seleccione Verificador
B19: Operador | E19: =+Operacion!K18 -> Selección Operador
B21: Lugar de carga | E21: =+Operacion!H14 -> 0
B25: Contacto: | E25: =+Operacion!H15 -> 0
E26: =+Operacion!L15 -> 0
B28: Lugar de descarga | E28: =+Operacion!H16 -> 0
B32: Contacto: | E32: =+Operacion!H17 -> 0
E33: =+Operacion!L17 -> 0
B35: Observaciones

Sheet 105-VW 9150
B2: Remito | E2: =+Operacion!G21 -> Seleccione Empresa | G2: Fecha: | H2: =+Operacion!D1 -> 46278
B4: Cliente | E4: =+Operacion!H22 -> 0 | G4: Hora de salida: | H4: =+Operacion!L22 -> 0
B6: Equipo: | E6: =+Operacion!B22 -> GDU105 | G6: Marca | H6: =VLOOKUP(E6,tablaequipo,6) -> VOLKSWAGEN
E7: =VLOOKUP(E6,tablaequipo,4) -> Camion | G7: Modelo | H7: =VLOOKUP(E6,tablaequipo,7) -> 9150
E8: =VLOOKUP(E6,tablaequipo,5) -> 0 | G8: Patente | H8: =VLOOKUP(E6,tablaequipo,8) -> MRF 907
B10: Chofer: | E10: =+Operacion!D22 -> Seleccione Chofer
B13: Acompañantes: | D13: 1 | E13: =+Operacion!D23 -> Selección Acompanante | G13: 4 | H13: =+Operacion!D26 -> Selección Acompanante
D14: 2 | E14: =+Operacion!D24 -> Selección Acompanante | G14: 5 | H14: =+Operacion!D27 -> Selección Acompanante
D15: 3 | E15: =+Operacion!D25 -> Selección Acompanante | G15: 6 | H15: =+Operacion!D28 -> Selección Acompanante
B17: Verificador: | E17: =+Operacion!H27 -> Seleccione Verificador
B19: Operador | E19: =+Operacion!K27 -> Selección Operador
B21: Lugar de carga | E21: =+Operacion!H23 -> 0
B25: Contacto: | E25: =+Operacion!H24 -> 0
E26: =+Operacion!L24 -> 0
B28: Lugar de descarga | E28: =+Operacion!H25 -> 0
B32: Contacto: | E32: =+Operacion!H26 -> 0
E33: =+Operacion!L26 -> 0
B35: Observaciones

Sheet 106-Iveco Euro 220
B2: Remito | E2: =+Operacion!G30 -> Seleccione Empresa | G2: Fecha: | H2: =+Operacion!D1 -> 46278
B4: Cliente | E4: =+Operacion!H31 -> 0 | G4: Hora de salida: | H4: =+Operacion!L31 -> 0
B6: Equipo: | E6: =+Operacion!B31 -> GDU106 | G6: Marca | H6: =VLOOKUP(E6,tablaequipo,6) -> IVECO
E7: =VLOOKUP(E6,tablaequipo,4) -> Camion | G7: Modelo | H7: =VLOOKUP(E6,tablaequipo,7) -> EURO 220
E8: =VLOOKUP(E6,tablaequipo,5) -> 0 | G8: Patente | H8: =VLOOKUP(E6,tablaequipo,8) -> HOD 216
B10: Chofer: | E10: =+Operacion!D31 -> Seleccione Chofer | G10: =+Operacion!F36 -> GDU000 | H10: =VLOOKUP(G10,tablatractor,6) -> 0
G11: =VLOOKUP(G10,tablatractor,3) -> Seleccione Equipo | H11: =VLOOKUP(G10,tablatractor,4) -> 0
B13: Acompañantes: | D13: 1 | E13: =+Operacion!D32 -> Selección Acompanante | G13: 4 | H13: =+Operacion!D35 -> Selección Acompanante
D14: 2 | E14: =+Operacion!D33 -> Selección Acompanante | G14: 5 | H14: =+Operacion!D36 -> Selección Acompanante
D15: 3 | E15: =+Operacion!D34 -> Selección Acompanante | G15: 6 | H15: =+Operacion!D37 -> Selección Acompanante
B17: Verificador: | E17: =+Operacion!H36 -> Seleccione Verificador
B19: Operador | E19: =+Operacion!K36 -> Selección Operador
B21: Lugar de carga | E21: =+Operacion!H32 -> 0
B25: Contacto: | E25: =+Operacion!H33 -> 0
E26: =+Operacion!L33 -> 0
B28: Lugar de descarga | E28: =+Operacion!H34 -> 0
B32: Contacto: | E32: =+Operacion!H35 -> 0
E33: =+Operacion!L35 -> 0
B35: Observaciones

Sheet 110-Iveco Tector
B2: Remito | E2: =+Operacion!G39 -> Seleccione Empresa | G2: Fecha: | H2: =+Operacion!D1 -> 46278
B4: Cliente | E4: =+Operacion!H40 -> 0 | G4: Hora de salida: | H4: =+Operacion!L40 -> 0
B6: Equipo: | E6: =+Operacion!B40 -> GDU110 | G6: Marca | H6: =VLOOKUP(E6,tablaequipo,6) -> IVECO
E7: =VLOOKUP(E6,tablaequipo,4) -> Camion | G7: Modelo | H7: =VLOOKUP(E6,tablaequipo,7) -> 170 E 22
E8: =VLOOKUP(E6,tablaequipo,5) -> 0 | G8: Patente | H8: =VLOOKUP(E6,tablaequipo,8) -> AC 223 HV
B10: Chofer: | E10: =+Operacion!D40 -> Seleccione Chofer
B13: Acompañantes: | D13: 1 | E13: =+Operacion!D41 -> Selección Acompanante | G13: 4 | H13: =+Operacion!D44 -> Selección Acompanante
D14: 2 | E14: =+Operacion!D42 -> Selección Acompanante | G14: 5 | H14: =+Operacion!D45 -> Selección Acompanante
D15: 3 | E15: =+Operacion!D43 -> Selección Acompanante | G15: 6 | H15: =+Operacion!D46 -> Selección Acompanante
B17: Verificador: | E17: =+Operacion!#REF! -> #REF!
B19: Operador | E19: =+Operacion!#REF! -> #REF!
B21: Lugar de carga | E21: =+Operacion!H41 -> 0
B25: Contacto: | E25: =+Operacion!H42 -> 0
E26: =+Operacion!L42 -> 0
B28: Lugar de descarga | E28: =+Operacion!H43 -> 0
B32: Contacto: | E32: =+Operacion!H44 -> 0
E33: =+Operacion!L44 -> 0
B35: Observaciones

Sheet 111-Iveco DS - 240
B2: Remito | E2: =+Operacion!G48 -> Seleccione Empresa | G2: Fecha: | H2: =+Operacion!D1 -> 46278
B4: Cliente | E4: =+Operacion!H49 -> 0 | G4: Hora de salida: | H4: =+Operacion!L49 -> 0
B6: Equipo: | E6: =+Operacion!B49 -> 111 | G6: Marca | H6: =VLOOKUP(E6,tablaequipo,6) -> IVECO
E7: =VLOOKUP(E6,tablaequipo,4) -> Camion | G7: Modelo | H7: =VLOOKUP(E6,tablaequipo,7) -> DS - 240
E8: =VLOOKUP(E6,tablaequipo,5) -> 0 | G8: Patente | H8: =VLOOKUP(E6,tablaequipo,8) -> AF009EJ
B10: Chofer: | E10: =+Operacion!D49 -> Seleccione Chofer | G10: =+Operacion!F54 -> GDU000 | H10: =VLOOKUP(G10,tablatractor,6) -> 0
G11: =VLOOKUP(G10,tablatractor,3) -> Seleccione Equipo | H11: =VLOOKUP(G10,tablatractor,4) -> 0
B13: Acompañantes: | D13: 1 | E13: =+Operacion!D50 -> Selección Acompanante | G13: 4 | H13: =+Operacion!D54 -> Selección Acompanante
D14: 2 | E14: =+Operacion!D51 -> Selección Acompanante | G14: 5 | H14: =+Operacion!D53 -> Selección Acompanante
D15: 3 | E15: =+Operacion!D52 -> Selección Acompanante | G15: 6 | H15: =+Operacion!D55 -> Selección Acompanante
B17: Verificador: | E17: =+Operacion!H54 -> Seleccione Verificador
B19: Operador | E19: =+Operacion!K54 -> Selección Operador
B21: Lugar de carga | E21: =+Operacion!H50 -> 0
B25: Contacto: | E25: =+Operacion!H51 -> 0
E26: =+Operacion!L51 -> 0
B28: Lugar de descarga | E28: =+Operacion!H52 -> 0
B32: Contacto: | E32: =+Operacion!H53 -> 0
E33: =+Operacion!L53 -> 0
B35: Observaciones

Sheet 113-Iveco DS - 240
B2: Remito | E2: =+Operacion!G57 -> Seleccione Empresa | G2: Fecha: | H2: =+Operacion!D1 -> 46278
B4: Cliente | E4: =+Operacion!H58 -> 0 | G4: Hora de salida: | H4: =+Operacion!L58 -> 0
B6: Equipo: | E6: =+Operacion!B58 -> GDU113 | G6: Marca | H6: =VLOOKUP(E6,tablaequipo,6) -> IVECO
E7: =VLOOKUP(E6,tablaequipo,4) -> Camion | G7: Modelo | H7: =VLOOKUP(E6,tablaequipo,7) -> TECTOR 240
E8: =VLOOKUP(E6,tablaequipo,5) -> 0 | G8: Patente | H8: =VLOOKUP(E6,tablaequipo,8) -> AG368PJ
B10: Chofer: | E10: =Operacion!D58 -> Seleccione Chofer | G10: =+Operacion!F63 -> GDU000 | H10: =VLOOKUP(G10,tablatractor,6) -> 0
G11: =VLOOKUP(G10,tablatractor,3) -> Seleccione Equipo | H11: =VLOOKUP(G10,tablatractor,4) -> 0
B13: Acompañantes: | D13: 1 | E13: =Operacion!D59 -> Selección Acompanante | G13: 4 | H13: =Operacion!D62 -> Selección Acompanante
D14: 2 | E14: =Operacion!D60 -> Selección Acompanante | G14: 5 | H14: =Operacion!D63 -> Selección Acompanante
D15: 3 | E15: =Operacion!D61 -> Selección Acompanante | G15: 6 | H15: =Operacion!D64 -> Selección Acompanante
B17: Verificador: | E17: =+Operacion!H63 -> Seleccione Verificador
B19: Operador | E19: =+Operacion!K63 -> Selección Operador
B21: Lugar de carga | E21: =+Operacion!H59 -> 0
B25: Contacto: | E25: =+Operacion!H60 -> 0
E26: =+Operacion!L60 -> 0
B28: Lugar de descarga | E28: =+Operacion!H61 -> 0
B32: Contacto: | E32: =+Operacion!H62 -> 0
E33: =+Operacion!L62 -> 0
B35: Observaciones

Sheet 109-Scania
B2: Remito | E2: =+Operacion!G66 -> Seleccione Empresa | G2: Fecha: | H2: =+Operacion!D1 -> 46278
B4: Cliente | E4: =+Operacion!H67 -> 0 | G4: Hora de salida: | H4: =+Operacion!L67 -> 0
B6: Equipo: | E6: =+Operacion!B67 -> GDU109 | G6: Marca | H6: =VLOOKUP(E6,tablaequipo,6) -> SCANIA
E7: =VLOOKUP(E6,tablaequipo,4) -> Tractor | G7: Modelo | H7: =VLOOKUP(E6,tablaequipo,7) -> G410
E8: =VLOOKUP(E6,tablaequipo,5) -> 0 | G8: Patente | H8: =VLOOKUP(E6,tablaequipo,8) -> PBA 177
B10: Chofer: | E10: =+Operacion!D67 -> Seleccione Chofer | G10: =+Operacion!F72 -> GDU200 | H10: =VLOOKUP(G10,tablatractor,6) -> GEV 193
G11: =VLOOKUP(G10,tablatractor,3) -> Carreton | H11: =VLOOKUP(G10,tablatractor,4) -> SALTO
B13: Acompañantes: | D13: 1 | E13: =+Operacion!D68 -> Selección Acompanante | G13: 4 | H13: =+Operacion!D71 -> Selección Acompanante
D14: 2 | E14: =+Operacion!D69 -> Selección Acompanante | G14: 5 | H14: =+Operacion!D72 -> Selección Acompanante
D15: 3 | E15: =+Operacion!D70 -> Selección Acompanante | G15: 6 | H15: =+Operacion!D73 -> Selección Acompanante
B17: Verificador: | E17: =+Operacion!H72 -> Seleccione Verificador
B19: Operador | E19: =+Operacion!K72 -> Selección Operador
B21: Lugar de carga | E21: =+Operacion!H68 -> 0
B25: Contacto: | E25: =+Operacion!H69 -> 0
E26: =+Operacion!L69 -> 0
B28: Lugar de descarga | E28: =+Operacion!H70 -> 0
B32: Contacto: | E32: =+Operacion!H71 -> 0
E33: =+Operacion!L71 -> 0
B35: Observaciones

Sheet 112-Iveco DS
B2: Remito | E2: =+Operacion!G75 -> Seleccione Empresa | G2: Fecha: | H2: =+Operacion!D1 -> 46278
B4: Cliente | E4: =+Operacion!H76 -> 0 | G4: Hora de salida: | H4: =+Operacion!L76 -> 0
B6: Equipo: | E6: =+Operacion!B76 -> GDU112 | G6: Marca | H6: =VLOOKUP(E6,tablaequipo,6) -> IVECO
E7: =VLOOKUP(E6,tablaequipo,4) -> Tractor | G7: Modelo | H7: =VLOOKUP(E6,tablaequipo,7) -> STRALIS - 440
E8: =VLOOKUP(E6,tablaequipo,5) -> 0 | G8: Patente | H8: =VLOOKUP(E6,tablaequipo,8) -> AF442SD
B10: Chofer: | E10: =+Operacion!D76 -> Seleccione Chofer | G10: =+Operacion!F81 -> GDU300 | H10: =VLOOKUP(G10,tablatractor,6) -> SNN 095
G11: =VLOOKUP(G10,tablatractor,3) -> Semirremolque | H11: =VLOOKUP(G10,tablatractor,4) -> GOMATRO
B13: Acompañantes: | D13: 1 | E13: =+Operacion!D77 -> Selección Acompanante | G13: 4 | H13: =+Operacion!D80 -> Selección Acompanante
D14: 2 | E14: =+Operacion!D78 -> Selección Acompanante | G14: 5 | H14: =+Operacion!D81 -> Selección Acompanante
D15: 3 | E15: =+Operacion!D79 -> Selección Acompanante | G15: 6 | H15: =+Operacion!D82 -> Selección Acompanante
B17: Verificador: | E17: =+Operacion!H81 -> Seleccione Verificador
B19: Operador | E19: =+Operacion!K81 -> Selección Operador
B21: Lugar de carga | E21: =+Operacion!H77 -> 0
B25: Contacto: | E25: =+Operacion!H78 -> 0
E26: =+Operacion!L78 -> 0
B28: Lugar de descarga | E28: =+Operacion!H79 -> 0
B32: Contacto: | E32: =+Operacion!H80 -> 0
E33: =+Operacion!L80 -> 0
B35: Observaciones

Sheet 402-Autoelevador
B2: Remito | E2: =+Operacion!G84 -> Universal Cranes | G2: Fecha: | H2: =+Operacion!D1 -> 46278
B4: Cliente | E4: =+Operacion!H85 -> PEALCO SA | G4: Hora de salida: | H4: =+Operacion!L85 -> 0.29166667
B6: Equipo: | E6: =+Operacion!B85 -> GDU402 | G6: Marca | H6: =VLOOKUP(E6,tablaequipo,6) -> HELI
E7: =VLOOKUP(E6,tablaequipo,4) -> Autoelevador | G7: Modelo | H7: =VLOOKUP(E6,tablaequipo,7) -> 7500
E8: =VLOOKUP(E6,tablaequipo,5) -> 7.5 | G8: Patente | H8: =VLOOKUP(E6,tablaequipo,8) -> BTX 078
B10: Chofer: | E10: =+Operacion!D85 -> 0
B13: Acompañantes: | D13: 1 | E13: =+Operacion!D86 -> 0 | G13: 4 | H13: =+Operacion!D89 -> 0
D14: 2 | E14: =+Operacion!D87 -> 0 | G14: 5 | H14: =+Operacion!D90 -> 0
D15: 3 | E15: =+Operacion!D88 -> 0 | G15: 6 | H15: =+Operacion!D91 -> 0
B17: Verificador: | E17: =+Operacion!H90 -> Seleccione Verificador
B19: Operador | E19: =+Operacion!K90 -> Recines Alejandro
B21: Lugar de carga | E21: =+Operacion!H86 -> TORTUGUITAS - VER UBICACIÓN
B25: Contacto: | E25: =+Operacion!H87 -> JOSE
E26: =+Operacion!L87 -> 15-3903-0846
B28: Lugar de descarga | E28: =+Operacion!H88 -> 0
B32: Contacto: | E32: =+Operacion!H89 -> 0
E33: =+Operacion!L89 -> 0
B35: Observaciones | E35: incluir las observaciones correpondientes

Sheet 403-Autoelevador
B2: Remito | E2: =+Operacion!G93 -> Seleccione Empresa | G2: Fecha: | H2: =+Operacion!D1 -> 46278
B4: Cliente | E4: =+Operacion!H94 -> 0 | G4: Hora de salida: | H4: =+Operacion!L94 -> 0
B6: Equipo: | E6: =+Operacion!B94 -> GDU403 | G6: Marca | H6: =VLOOKUP(E6,tablaequipo,6) -> KOMATSU
E7: =VLOOKUP(E6,tablaequipo,4) -> Autoelevador | G7: Modelo | H7: =VLOOKUP(E6,tablaequipo,7) -> 5500
E8: =VLOOKUP(E6,tablaequipo,5) -> 5.5 | G8: Patente | H8: =VLOOKUP(E6,tablaequipo,8) -> -
B10: Chofer: | E10: =+Operacion!D94 -> Seleccione Chofer
B13: Acompañantes: | D13: 1 | E13: =+Operacion!D95 -> Selección Acompanante | G13: 4 | H13: =+Operacion!D98 -> Selección Acompanante
D14: 2 | E14: =+Operacion!D96 -> Selección Acompanante | G14: 5 | H14: =+Operacion!D99 -> Selección Acompanante
D15: 3 | E15: =+Operacion!D97 -> Selección Acompanante | G15: 6 | H15: =+Operacion!D100 -> Selección Acompanante
B17: Verificador: | E17: =+Operacion!H99 -> Seleccione Verificador
B19: Operador | E19: =+Operacion!K99 -> Selección Operador
B21: Lugar de carga | E21: =+Operacion!H95 -> 0
B25: Contacto: | E25: =+Operacion!H96 -> 0
E26: =+Operacion!L96 -> 0
B28: Lugar de descarga | E28: =+Operacion!H97 -> 0
B32: Contacto: | E32: =+Operacion!H98 -> 0
E33: =+Operacion!L98 -> 0
B35: Observaciones | E35: incluir las observaciones correpondientes

Sheet 404-Autoelevador
B2: Remito | E2: =+Operacion!G102 -> Seleccione Empresa | G2: Fecha: | H2: =+Operacion!D1 -> 46278
B4: Cliente | E4: =+Operacion!H103 -> 0 | G4: Hora de salida: | H4: =+Operacion!L103 -> 0
B6: Equipo: | E6: =+Operacion!B103 -> GDU404 | G6: Marca | H6: =VLOOKUP(E6,tablaequipo,6) -> HYUNDAI
E7: =VLOOKUP(E6,tablaequipo,4) -> Autoelevador | G7: Modelo | H7: =VLOOKUP(E6,tablaequipo,7) -> DD 30 E
E8: =VLOOKUP(E6,tablaequipo,5) -> 3 | G8: Patente | H8: =VLOOKUP(E6,tablaequipo,8) -> -
B10: Chofer: | E10: =+Operacion!D103 -> Seleccione Chofer
B13: Acompañantes: | D13: 1 | E13: =+Operacion!D104 -> Selección Acompanante | G13: 4 | H13: =+Operacion!D107 -> Selección Acompanante
D14: 2 | E14: =+Operacion!D105 -> Selección Acompanante | G14: 5 | H14: =+Operacion!D108 -> Selección Acompanante
D15: 3 | E15: =+Operacion!D106 -> Selección Acompanante | G15: 6 | H15: =+Operacion!D109 -> Selección Acompanante
B17: Verificador: | E17: =+Operacion!#REF! -> #REF!
B19: Operador | E19: =+Operacion!#REF! -> #REF!
B21: Lugar de carga | E21: =+Operacion!H104 -> 0
B25: Contacto: | E25: =+Operacion!H105 -> 0
E26: =+Operacion!L105 -> 0
B28: Lugar de descarga | E28: =+Operacion!H106 -> 0
B32: Contacto: | E32: =+Operacion!H107 -> 0
E33: =+Operacion!L107 -> 0
B35: Observaciones | E35: incluir las observaciones correpondientes

Sheet 405-Autoelevador 
B2: Remito | E2: =+Operacion!G111 -> Seleccione Empresa | G2: Fecha: | H2: =+Operacion!D1 -> 46278
B4: Cliente | E4: =+Operacion!H112 -> 0 | G4: Hora de salida: | H4: =+Operacion!L112 -> 0
B6: Equipo: | E6: =+Operacion!B112 -> GDU405 | G6: Marca | H6: =VLOOKUP(E6,tablaequipo,6) -> SINOBANG
E7: =VLOOKUP(E6,tablaequipo,4) -> Autoelevador | G7: Modelo | H7: =VLOOKUP(E6,tablaequipo,7) -> CPCD 70
E8: =VLOOKUP(E6,tablaequipo,5) -> 7 | G8: Patente | H8: =VLOOKUP(E6,tablaequipo,8) -> 0
B10: Chofer: | E10: =+Operacion!D112 -> Seleccione Chofer
B13: Acompañantes: | D13: 1 | E13: =+Operacion!D113 -> Selección Acompanante | G13: 4 | H13: =+Operacion!D116 -> Selección Acompanante
D14: 2 | E14: =+Operacion!D114 -> Selección Acompanante | G14: 5 | H14: =+Operacion!D117 -> Selección Acompanante
D15: 3 | E15: =+Operacion!D115 -> Selección Acompanante | G15: 6 | H15: =+Operacion!D118 -> Selección Acompanante
B17: Verificador: | E17: =+Operacion!H117 -> Seleccione Verificador
B19: Operador | E19: =+Operacion!K117 -> Selección Operador
B21: Lugar de carga | E21: =+Operacion!H113 -> 0
B25: Contacto: | E25: =+Operacion!H114 -> 0
E26: =+Operacion!L114 -> 0
B28: Lugar de descarga | E28: =+Operacion!H115 -> 0
B32: Contacto: | E32: =+Operacion!H116 -> 0
E33: =+Operacion!L116 -> 0
B35: Observaciones | E35: incluir las observaciones correpondientes

Sheet 406-Autoelevador
B2: Remito | E2: =+Operacion!G120 -> Seleccione Empresa | G2: Fecha: | H2: =+Operacion!D1 -> 46278
B4: Cliente | E4: =+Operacion!H121 -> 0 | G4: Hora de salida: | H4: =+Operacion!L121 -> 0
B6: Equipo: | E6: =+Operacion!B121 -> GDU406 | G6: Marca | H6: =VLOOKUP(E6,tablaequipo,6) -> SINOBANG
E7: =VLOOKUP(E6,tablaequipo,4) -> Autoelevador | G7: Modelo | H7: =VLOOKUP(E6,tablaequipo,7) -> CPCD 25
E8: =VLOOKUP(E6,tablaequipo,5) -> 2.5 | G8: Patente | H8: =VLOOKUP(E6,tablaequipo,8) -> 0
B10: Chofer: | E10: =+Operacion!D121 -> Seleccione Chofer
B13: Acompañantes: | D13: 1 | E13: =+Operacion!D122 -> Selección Acompanante | G13: 4 | H13: =+Operacion!D125 -> Selección Acompanante
D14: 2 | E14: =+Operacion!D123 -> Selección Acompanante | G14: 5 | H14: =+Operacion!D126 -> Selección Acompanante
D15: 3 | E15: =+Operacion!D124 -> Selección Acompanante | G15: 6 | H15: =+Operacion!D127 -> Selección Acompanante
B17: Verificador: | E17: =+Operacion!#REF! -> #REF!
B19: Operador | E19: =+Operacion!#REF! -> #REF!
B21: Lugar de carga | E21: =+Operacion!H122 -> 0
B25: Contacto: | E25: =+Operacion!H123 -> 0
E26: =+Operacion!L123 -> 0
B28: Lugar de descarga | E28: =+Operacion!H124 -> 0
B32: Contacto: | E32: =+Operacion!H125 -> 0
E33: =+Operacion!L125 -> 0
B35: Observaciones | E35: incluir las observaciones correpondientes

Sheet 407-Autoelevador
B2: Remito | E2: =+Operacion!G129 -> Seleccione Empresa | G2: Fecha: | H2: =+Operacion!D1 -> 46278
B4: Cliente | E4: =+Operacion!H130 -> 0 | G4: Hora de salida: | H4: =+Operacion!L130 -> 0
B6: Equipo: | E6: =+Operacion!B130 -> GDU407 | G6: Marca | H6: =VLOOKUP(E6,tablaequipo,6) -> SINOBANG
E7: =VLOOKUP(E6,tablaequipo,4) -> Autoelevador | G7: Modelo | H7: =VLOOKUP(E6,tablaequipo,7) -> CPCD 30
E8: =VLOOKUP(E6,tablaequipo,5) -> 3 | G8: Patente | H8: =VLOOKUP(E6,tablaequipo,8) -> 0
B10: Chofer: | E10: =+Operacion!D130 -> Seleccione Chofer
B13: Acompañantes: | D13: 1 | E13: =+Operacion!D131 -> Selección Acompanante | G13: 4 | H13: =+Operacion!D134 -> Selección Acompanante
D14: 2 | E14: =+Operacion!D132 -> Selección Acompanante | G14: 5 | H14: =+Operacion!D135 -> Selección Acompanante
D15: 3 | E15: =+Operacion!D133 -> Selección Acompanante | G15: 6 | H15: =+Operacion!D136 -> Selección Acompanante
B17: Verificador: | E17: =+Operacion!H135 -> Seleccione Verificador
B19: Operador | E19: =+Operacion!K135 -> Selección Operador
B21: Lugar de carga | E21: =+Operacion!H131 -> 0
B25: Contacto: | E25: =+Operacion!H132 -> 0
E26: =+Operacion!L132 -> 0
B28: Lugar de descarga | E28: =+Operacion!H133 -> 0
B32: Contacto: | E32: =+Operacion!H134 -> 0
E33: =+Operacion!L134 -> 0
B35: Observaciones | E35: incluir las observaciones correpondientes

Sheet 408-Autoelevador 
B2: Remito | E2: =+Operacion!G138 -> Seleccione Empresa | G2: Fecha: | H2: =+Operacion!D1 -> 46278
B4: Cliente | E4: =+Operacion!H139 -> 0 | G4: Hora de salida: | H4: =+Operacion!L139 -> 0
B6: Equipo: | E6: =+Operacion!B139 -> GDU408 | G6: Marca | H6: =VLOOKUP(E6,tablaequipo,6) -> SINOBANG
E7: =VLOOKUP(E6,tablaequipo,4) -> Autoelevador | G7: Modelo | H7: =VLOOKUP(E6,tablaequipo,7) -> CPCD 100
E8: =VLOOKUP(E6,tablaequipo,5) -> 10 | G8: Patente | H8: =VLOOKUP(E6,tablaequipo,8) -> 0
B10: Chofer: | E10: =+Operacion!D139 -> 0
B13: Acompañantes: | D13: 1 | E13: =+Operacion!D140 -> 0 | G13: 4 | H13: =+Operacion!D143 -> 0
D14: 2 | E14: =+Operacion!D141 -> 0 | G14: 5 | H14: =+Operacion!D144 -> 0
D15: 3 | E15: =+Operacion!D142 -> 0 | G15: 6 | H15: =+Operacion!D145 -> 0
B17: Verificador: | E17: =+Operacion!H144 -> Seleccione Verificador
B19: Operador | E19: =+Operacion!K144 -> Selección Operador
B21: Lugar de carga | E21: =+Operacion!H140 -> 0
B25: Contacto: | E25: =+Operacion!H141 -> 0
E26: =+Operacion!L141 -> 0
B28: Lugar de descarga | E28: =+Operacion!H142 -> 0
B32: Contacto: | E32: =+Operacion!H143 -> 0
E33: =+Operacion!L143 -> 0
B35: Observaciones | E35: incluir las observaciones correpondientes

Sheet 454-Manipiulador
B2: Remito | E2: =+Operacion!G147 -> Seleccione Empresa | G2: Fecha: | H2: =+Operacion!D1 -> 46278
B4: Cliente | E4: =+Operacion!H148 -> 0 | G4: Hora de salida: | H4: =+Operacion!L148 -> 0
B6: Equipo: | E6: =+Operacion!B148 -> GDU454 | G6: Marca | H6: =VLOOKUP(E6,tablaequipo,6) -> Haulote
E7: =VLOOKUP(E6,tablaequipo,4) -> Manipulador | G7: Modelo | H7: =VLOOKUP(E6,tablaequipo,7) -> Hlt4014
E8: =VLOOKUP(E6,tablaequipo,5) -> 0 | G8: Patente | H8: =VLOOKUP(E6,tablaequipo,8) -> 0
B10: Chofer: | E10: =+Operacion!D148 -> Seleccione Chofer
B13: Acompañantes: | D13: 1 | E13: =+Operacion!D149 -> Selección Acompanante | G13: 4 | H13: =+Operacion!D152 -> Selección Acompanante
D14: 2 | E14: =+Operacion!D150 -> Selección Acompanante | G14: 5 | H14: =+Operacion!D153 -> Selección Acompanante
D15: 3 | E15: =+Operacion!D151 -> Selección Acompanante | G15: 6 | H15: =+Operacion!D154 -> Selección Acompanante
B17: Verificador: | E17: =+Operacion!#REF! -> #REF!
B19: Operador | E19: =+Operacion!#REF! -> #REF!
B21: Lugar de carga | E21: =+Operacion!H149 -> 0
B25: Contacto: | E25: =+Operacion!H150 -> 0
E26: =+Operacion!L150 -> 0
B28: Lugar de descarga | E28: =+Operacion!H151 -> 0
B32: Contacto: | E32: =+Operacion!H152 -> 0
E33: =+Operacion!L152 -> 0
B35: Observaciones

Sheet 701-Grua Alquilada
B2: Remito | E2: =+Operacion!G156 -> Seleccione Empresa | G2: Fecha: | H2: =+Operacion!D1 -> 46278
B4: Cliente | E4: =+Operacion!H157 -> 0 | G4: Hora de salida: | H4: =+Operacion!L157 -> 0
B6: Equipo: | E6: =+Operacion!B157 -> GDU701 | G6: Marca | H6: =VLOOKUP(E6,tablaequipo,6) -> Alguiler Grua
E7: =VLOOKUP(E6,tablaequipo,4) -> Grua | G7: Modelo | H7: =VLOOKUP(E6,tablaequipo,7) -> 0
E8: =VLOOKUP(E6,tablaequipo,5) -> 0 | G8: Patente | H8: =VLOOKUP(E6,tablaequipo,8) -> 0
B10: Chofer: | E10: =+Operacion!D157 -> Seleccione Chofer
B13: Acompañantes: | D13: 1 | E13: =+Operacion!D158 -> Selección Acompanante | G13: 4 | H13: =+Operacion!D161 -> Selección Acompanante
D14: 2 | E14: =+Operacion!D159 -> Selección Acompanante | G14: 5 | H14: =+Operacion!D162 -> Selección Acompanante
D15: 3 | E15: =+Operacion!D160 -> Selección Acompanante | G15: 6 | H15: =+Operacion!D163 -> Selección Acompanante
B17: Verificador: | E17: =+Operacion!#REF! -> #REF!
B19: Operador | E19: =+Operacion!#REF! -> #REF!
B21: Lugar de carga | E21: =+Operacion!H158 -> 0
B25: Contacto: | E25: =+Operacion!H159 -> 0
E26: =+Operacion!L159 -> 0
B28: Lugar de descarga | E28: =+Operacion!H160 -> 0
B32: Contacto: | E32: =+Operacion!H161 -> 0
E33: =+Operacion!L161 -> 0
B35: Observaciones

Sheet 500-Liebherr 1030
B2: Remito | E2: =+Operacion!G165 -> Gruas Daniele | G2: Fecha: | H2: =+Operacion!D1 -> 46278
B4: Cliente | E4: =+Operacion!H166 -> IDENTIDAD CORPORATIVA ARGENTINA | G4: Hora de salida: | H4: =+Operacion!L166 -> 0.25
B6: Equipo: | E6: =+Operacion!B166 -> GDU500 | G6: Marca | H6: =VLOOKUP(E6,tablaequipo,6) -> LIEBHERR
E7: =VLOOKUP(E6,tablaequipo,4) -> Grua | G7: Modelo | H7: =VLOOKUP(E6,tablaequipo,7) -> LTM 1030
E8: =VLOOKUP(E6,tablaequipo,5) -> 30 | G8: Patente | H8: =VLOOKUP(E6,tablaequipo,8) -> -
B10: Chofer: | E10: =+Operacion!D166 -> Campos Fernandez Jose Antonio
B13: Acompañantes: | D13: 1 | E13: =+Operacion!D167 -> 0 | G13: 4 | H13: =+Operacion!D170 -> 0
D14: 2 | E14: =+Operacion!D168 -> 0 | G14: 5 | H14: =+Operacion!D171 -> 0
D15: 3 | E15: =+Operacion!D169 -> 0 | G15: 6 | H15: =+Operacion!D172 -> 0
B17: Verificador: | E17: =+Operacion!H171 -> Seleccione Verificador
B19: Operador | E19: =+Operacion!K171 -> Recines Alejandro
B21: Lugar de carga | E21: =+Operacion!H167 -> MAC DONALD´S - AV 14 N°5002, BERAZATEGUI
B25: Contacto: | E25: =+Operacion!H168 -> 0
E26: =+Operacion!L168 -> 0
B28: Lugar de descarga | E28: =+Operacion!H169 -> 0
B32: Contacto: | E32: =+Operacion!H170 -> 0
E33: =+Operacion!L170 -> 0
B35: Observaciones | E35: SERVICIO DE IZAJE DE PERSONAL MEDIANTE BARQUILLA ==REMITO MINIMO DE 10 HS == (ELLOS PONEN LA BARQUILLA )

Sheet 502-Liebherr 1070
B2: Remito | E2: =+Operacion!G174 -> Seleccione Empresa | G2: Fecha: | H2: =+Operacion!D1 -> 46278
