Workbook
Name a: #REF!
Name a: #REF!
Name a: #REF!
Name a: #REF!
Name a: #REF!
Name a: #REF!
Name a: #REF!
Name a: #REF!
Name a: #REF!
Name a: #REF!
Name a: #REF!
Name a: #REF!
Name a: #REF!
Name a: #REF!
Name a: #REF!
Name a: #REF!
Name a: #REF!
Name a: #REF!
Name a: #REF!
Name a: #REF!
Name a: #REF!
Name a: #REF!
Name a: #REF!
Name a: #REF!
Name a: #REF!
Name a: #REF!
Name a: #REF!
Name a: #REF!
Name a: #REF!
Name a: #REF!
Name a: #REF!
Name a: #REF!
Name aa: #REF!
Name aa: #REF!
Name aa: #REF!
Name aa: #REF!
Name aa: #REF!
Name aa: #REF!
Name aa: #REF!
Name aa: #REF!
Name aa: #REF!
Name aa: #REF!
Name aa: #REF!
Name aa: #REF!
Name aa: #REF!
Name aa: #REF!
Name aa: #REF!
Name aa: #REF!
Name aa: #REF!
Name aa: #REF!
Name aa: #REF!
Name aa: #REF!
Name aa: #REF!
Name aa: #REF!
Name aa: #REF!
Name aa: #REF!
Name aa: #REF!
Name aa: #REF!
Name aa: #REF!
Name aa: #REF!

Sheet Dia (1)
B1: Asignacion y uso de Vehiculos Livianos
B2: FECHA | D2: 46266
H3: Salida | J3: Llegada
B4: Interno | D4: Tipo | E4: Marca | F4: Modelo | G4: Personal Asignado | H4: Lugar | I4: Horario | J4: Lugar | K4: Horario | L4: Uso | M4: Observaciones | N4: Estado
A5: 1 | B5: GDU001 | C5: =VLOOKUP(B5,unidad,2) -> Liviano | D5: =VLOOKUP(B5,unidad,3) -> FIAT | E5: =VLOOKUP(B5,unidad,4) -> UNO | F5: =VLOOKUP(B5,unidad,5) -> EYI 197 | H5: Base | J5: Base | N5: 0 | O5: =VLOOKUP(N5,estado,3) -> Seleccione Estado
A6: =+A5+1 -> 2 | B6: GDU002 | C6: =VLOOKUP(B6,unidad,2) -> Liviano | D6: =VLOOKUP(B6,unidad,3) -> FIAT | E6: =VLOOKUP(B6,unidad,4) -> UNO | F6: =VLOOKUP(B6,unidad,5) -> ODQ 087 | H6: Base | J6: Base | N6: 0 | O6: =VLOOKUP(N6,estado,3) -> Seleccione Estado
A7: 4 | B7: GDU011 | C7: =VLOOKUP(B7,unidad,2) -> Liviano | D7: =VLOOKUP(B7,unidad,3) -> CHEVROLET | E7: =VLOOKUP(B7,unidad,4) -> CELTA | F7: =VLOOKUP(B7,unidad,5) -> MEE 670 | H7: Base | J7: Base | N7: 0 | O7: =VLOOKUP(N7,estado,3) -> Seleccione Estado
A8: 5 | B8: GDU053 | C8: =VLOOKUP(B8,unidad,2) -> Liviano | D8: =VLOOKUP(B8,unidad,3) -> FIAT | E8: =VLOOKUP(B8,unidad,4) -> FIORINO | F8: =VLOOKUP(B8,unidad,5) -> MHX 920 | H8: Base | J8: Base | N8: 0 | O8: =VLOOKUP(N8,estado,3) -> Seleccione Estado
A9: =+A8+1 -> 6 | B9: GDU061 | C9: =VLOOKUP(B9,unidad,2) -> Liviano | D9: =VLOOKUP(B9,unidad,3) -> RENAULT | E9: =VLOOKUP(B9,unidad,4) -> KANGOO | F9: =VLOOKUP(B9,unidad,5) -> AF 677 IV | H9: Base | J9: Base | N9: 0 | O9: =VLOOKUP(N9,estado,3) -> Seleccione Estado
A10: =+A9+1 -> 7 | B10: GDU055 | C10: =VLOOKUP(B10,unidad,2) -> Liviano | D10: =VLOOKUP(B10,unidad,3) -> VOLKSWAGEN | E10: =VLOOKUP(B10,unidad,4) -> AMAROK | F10: =VLOOKUP(B10,unidad,5) -> OGZ 054 | H10: Base | J10: Base | N10: 0 | O10: =VLOOKUP(N10,estado,3) -> Seleccione Estado
A11: =+A10+1 -> 8 | B11: GDU056 | C11: =VLOOKUP(B11,unidad,2) -> Liviano | D11: =VLOOKUP(B11,unidad,3) -> VOLKSWAGEN | E11: =VLOOKUP(B11,unidad,4) -> AMAROK | F11: =VLOOKUP(B11,unidad,5) -> AA 087 LA | H11: Base | J11: Base | N11: 0 | O11: =VLOOKUP(N11,estado,3) -> Seleccione Estado
A12: =+A11+1 -> 9 | B12: GDU057 | C12: =VLOOKUP(B12,unidad,2) -> Liviano | D12: =VLOOKUP(B12,unidad,3) -> VOLKSWAGEN | E12: =VLOOKUP(B12,unidad,4) -> AMAROK | F12: =VLOOKUP(B12,unidad,5) -> NZF 438 | H12: Base | J12: Base | N12: 0 | O12: =VLOOKUP(N12,estado,3) -> Seleccione Estado
A13: =+A12+1 -> 10 | B13: GDU064 | C13: =VLOOKUP(B13,unidad,2) -> Liviano | D13: =VLOOKUP(B13,unidad,3) -> FIAT | E13: =VLOOKUP(B13,unidad,4) -> STRADA | F13: =VLOOKUP(B13,unidad,5) -> AH210SR | H13: Base | J13: Base | N13: 0 | O13: =VLOOKUP(N13,estado,3) -> Seleccione Estado
A14: =+A13+1 -> 11 | B14: GDU065 | C14: =VLOOKUP(B14,unidad,2) -> Liviano | D14: =VLOOKUP(B14,unidad,3) -> FIAT | E14: =VLOOKUP(B14,unidad,4) -> FIORINO | F14: =VLOOKUP(B14,unidad,5) -> AH255OH | H14: Base | J14: Base | N14: 0 | O14: =VLOOKUP(N14,estado,3) -> Seleccione Estado
A15: =+A14+1 -> 12 | B15: GDU063 | C15: =VLOOKUP(B15,unidad,2) -> Liviano | D15: =VLOOKUP(B15,unidad,3) -> TOYOTA | E15: =VLOOKUP(B15,unidad,4) -> HILUX | F15: =VLOOKUP(B15,unidad,5) -> AD761JW | H15: Base | J15: Base | N15: 0 | O15: =VLOOKUP(N15,estado,3) -> Seleccione Estado
A16: =+A15+1 -> 13 | B16: GDU061 | C16: =VLOOKUP(B16,unidad,2) -> Liviano | D16: RENAULT | E16: KANGOO | F16: AF677IV | H16: Base | J16: Base | N16: 0 | O16: =VLOOKUP(N16,estado,3) -> Seleccione Estado
A17: =+A16+1 -> 14 | B17: GDU064 | C17: =VLOOKUP(B17,unidad,2) -> Liviano | D17: =VLOOKUP(B17,unidad,3) -> FIAT | E17: =VLOOKUP(B17,unidad,4) -> STRADA | F17: =VLOOKUP(B17,unidad,5) -> AH210SR | H17: Base | J17: Base | N17: 0 | O17: =VLOOKUP(N17,estado,3) -> Seleccione Estado
A18: =+A17+1 -> 15 | B18: GDU000 | C18: =VLOOKUP(B18,unidad,2) -> Selecciona Equipo | D18: =VLOOKUP(B18,unidad,3) -> 0 | E18: =VLOOKUP(B18,unidad,4) -> 0 | F18: =VLOOKUP(B18,unidad,5) -> 0 | H18: Base | J18: Base | N18: 0 | O18: =VLOOKUP(N18,estado,3) -> Seleccione Estado
A19: =+A18+1 -> 16 | B19: GDU000 | C19: =VLOOKUP(B19,unidad,2) -> Selecciona Equipo | D19: =VLOOKUP(B19,unidad,3) -> 0 | E19: =VLOOKUP(B19,unidad,4) -> 0 | F19: =VLOOKUP(B19,unidad,5) -> 0 | H19: Base | J19: Base | N19: 0 | O19: =VLOOKUP(N19,estado,3) -> Seleccione Estado
A20: =+A19+1 -> 17 | B20: GDU000 | C20: =VLOOKUP(B20,unidad,2) -> Selecciona Equipo | D20: =VLOOKUP(B20,unidad,3) -> 0 | E20: =VLOOKUP(B20,unidad,4) -> 0 | F20: =VLOOKUP(B20,unidad,5) -> 0 | H20: Base | J20: Base | N20: 0 | O20: =VLOOKUP(N20,estado,3) -> Seleccione Estado
A22: AÑO | B22: MES | C22: DIA
A23: 2022 | B23: 7 | C23: 1

Sheet Dia (2)
B1: Asignacion y uso de Vehiculos Livianos
B2: FECHA | D2: ='Dia (1)'!D2+_xlfn.SHEET()-1 -> 46267
H3: Salida | J3: Llegada
B4: Interno | D4: Tipo | E4: Marca | F4: Modelo | G4: Personal Asignado | H4: Lugar | I4: Horario | J4: Lugar | K4: Horario | L4: Uso | M4: Observaciones | N4: Estado
A5: 1 | B5: GDU001 | C5: =VLOOKUP(B5,unidad,2) -> Liviano | D5: =VLOOKUP(B5,unidad,3) -> FIAT | E5: =VLOOKUP(B5,unidad,4) -> UNO | F5: =VLOOKUP(B5,unidad,5) -> EYI 197 | H5: Base | J5: Base | N5: 0 | O5: =VLOOKUP(N5,estado,3) -> Seleccione Estado
A6: =+A5+1 -> 2 | B6: GDU002 | C6: =VLOOKUP(B6,unidad,2) -> Liviano | D6: =VLOOKUP(B6,unidad,3) -> FIAT | E6: =VLOOKUP(B6,unidad,4) -> UNO | F6: =VLOOKUP(B6,unidad,5) -> ODQ 087 | H6: Base | J6: Base | N6: 0 | O6: =VLOOKUP(N6,estado,3) -> Seleccione Estado
A7: 3 | B7: GDU011 | C7: =VLOOKUP(B7,unidad,2) -> Liviano | D7: =VLOOKUP(B7,unidad,3) -> CHEVROLET | E7: =VLOOKUP(B7,unidad,4) -> CELTA | F7: =VLOOKUP(B7,unidad,5) -> MEE 670 | H7: Base | J7: Base | N7: 0 | O7: =VLOOKUP(N7,estado,3) -> Seleccione Estado
A8: 4 | B8: GDU053 | C8: =VLOOKUP(B8,unidad,2) -> Liviano | D8: =VLOOKUP(B8,unidad,3) -> FIAT | E8: =VLOOKUP(B8,unidad,4) -> FIORINO | F8: =VLOOKUP(B8,unidad,5) -> MHX 920 | H8: Base | J8: Base | N8: 0 | O8: =VLOOKUP(N8,estado,3) -> Seleccione Estado
A9: 5 | B9: GDU061 | C9: =VLOOKUP(B9,unidad,2) -> Liviano | D9: =VLOOKUP(B9,unidad,3) -> RENAULT | E9: =VLOOKUP(B9,unidad,4) -> KANGOO | F9: =VLOOKUP(B9,unidad,5) -> AF 677 IV | H9: Base | J9: Base | N9: 0 | O9: =VLOOKUP(N9,estado,3) -> Seleccione Estado
A10: 6 | B10: GDU055 | C10: =VLOOKUP(B10,unidad,2) -> Liviano | D10: =VLOOKUP(B10,unidad,3) -> VOLKSWAGEN | E10: =VLOOKUP(B10,unidad,4) -> AMAROK | F10: =VLOOKUP(B10,unidad,5) -> OGZ 054 | H10: Base | J10: Base | N10: 0 | O10: =VLOOKUP(N10,estado,3) -> Seleccione Estado
A11: 7 | B11: GDU056 | C11: =VLOOKUP(B11,unidad,2) -> Liviano | D11: =VLOOKUP(B11,unidad,3) -> VOLKSWAGEN | E11: =VLOOKUP(B11,unidad,4) -> AMAROK | F11: =VLOOKUP(B11,unidad,5) -> AA 087 LA | H11: Base | J11: Base | N11: 0 | O11: =VLOOKUP(N11,estado,3) -> Seleccione Estado
A12: 8 | B12: GDU057 | C12: =VLOOKUP(B12,unidad,2) -> Liviano | D12: =VLOOKUP(B12,unidad,3) -> VOLKSWAGEN | E12: =VLOOKUP(B12,unidad,4) -> AMAROK | F12: =VLOOKUP(B12,unidad,5) -> NZF 438 | H12: Base | J12: Base | N12: 0 | O12: =VLOOKUP(N12,estado,3) -> Seleccione Estado
A13: 9 | B13: GDU064 | C13: =VLOOKUP(B13,unidad,2) -> Liviano | D13: =VLOOKUP(B13,unidad,3) -> FIAT | E13: =VLOOKUP(B13,unidad,4) -> STRADA | F13: =VLOOKUP(B13,unidad,5) -> AH210SR | H13: Base | J13: Base | N13: 0 | O13: =VLOOKUP(N13,estado,3) -> Seleccione Estado
A14: 10 | B14: GDU065 | C14: =VLOOKUP(B14,unidad,2) -> Liviano | D14: =VLOOKUP(B14,unidad,3) -> FIAT | E14: =VLOOKUP(B14,unidad,4) -> FIORINO | F14: =VLOOKUP(B14,unidad,5) -> AH255OH | H14: Base | J14: Base | N14: 0 | O14: =VLOOKUP(N14,estado,3) -> Seleccione Estado
A15: 11 | B15: GDU063 | C15: =VLOOKUP(B15,unidad,2) -> Liviano | D15: =VLOOKUP(B15,unidad,3) -> TOYOTA | E15: =VLOOKUP(B15,unidad,4) -> HILUX | F15: =VLOOKUP(B15,unidad,5) -> AD761JW | H15: Base | J15: Base | N15: 0 | O15: =VLOOKUP(N15,estado,3) -> Seleccione Estado
A16: 12 | B16: GDU061 | C16: =VLOOKUP(B16,unidad,2) -> Liviano | D16: RENAULT | E16: KANGOO | F16: AF677IV | H16: Base | J16: Base | N16: 0 | O16: =VLOOKUP(N16,estado,3) -> Seleccione Estado
A17: 13 | B17: GDU064 | C17: =VLOOKUP(B17,unidad,2) -> Liviano | D17: =VLOOKUP(B17,unidad,3) -> FIAT | E17: =VLOOKUP(B17,unidad,4) -> STRADA | F17: =VLOOKUP(B17,unidad,5) -> AH210SR | H17: Base | J17: Base | N17: 0 | O17: =VLOOKUP(N17,estado,3) -> Seleccione Estado
A18: 14 | B18: GDU000 | C18: =VLOOKUP(B18,unidad,2) -> Selecciona Equipo | D18: =VLOOKUP(B18,unidad,3) -> 0 | E18: =VLOOKUP(B18,unidad,4) -> 0 | F18: =VLOOKUP(B18,unidad,5) -> 0 | H18: Base | J18: Base | N18: 0 | O18: =VLOOKUP(N18,estado,3) -> Seleccione Estado
A19: 15 | B19: GDU000 | C19: =VLOOKUP(B19,unidad,2) -> Selecciona Equipo | D19: =VLOOKUP(B19,unidad,3) -> 0 | E19: =VLOOKUP(B19,unidad,4) -> 0 | F19: =VLOOKUP(B19,unidad,5) -> 0 | H19: Base | J19: Base | N19: 0 | O19: =VLOOKUP(N19,estado,3) -> Seleccione Estado
A20: 16 | B20: GDU000 | C20: =VLOOKUP(B20,unidad,2) -> Selecciona Equipo | D20: =VLOOKUP(B20,unidad,3) -> 0 | E20: =VLOOKUP(B20,unidad,4) -> 0 | F20: =VLOOKUP(B20,unidad,5) -> 0 | H20: Base | J20: Base | N20: 0 | O20: =VLOOKUP(N20,estado,3) -> Seleccione Estado

Sheet Dia (3)
B1: Asignacion y uso de Vehiculos Livianos
B2: FECHA | D2: ='Dia (1)'!D2+_xlfn.SHEET()-1 -> 46268
H3: Salida | J3: Llegada
B4: Interno | D4: Tipo | E4: Marca | F4: Modelo | G4: Personal Asignado | H4: Lugar | I4: Horario | J4: Lugar | K4: Horario | L4: Uso | M4: Observaciones | N4: Estado
A5: 1 | B5: GDU001 | C5: =VLOOKUP(B5,unidad,2) -> Liviano | D5: =VLOOKUP(B5,unidad,3) -> FIAT | E5: =VLOOKUP(B5,unidad,4) -> UNO | F5: =VLOOKUP(B5,unidad,5) -> EYI 197 | H5: Base | J5: Base | N5: 0 | O5: =VLOOKUP(N5,estado,3) -> Seleccione Estado
A6: =+A5+1 -> 2 | B6: GDU002 | C6: =VLOOKUP(B6,unidad,2) -> Liviano | D6: =VLOOKUP(B6,unidad,3) -> FIAT | E6: =VLOOKUP(B6,unidad,4) -> UNO | F6: =VLOOKUP(B6,unidad,5) -> ODQ 087 | H6: Base | J6: Base | N6: 0 | O6: =VLOOKUP(N6,estado,3) -> Seleccione Estado
A7: =+A6+1 -> 3 | B7: GDU011 | C7: =VLOOKUP(B7,unidad,2) -> Liviano | D7: =VLOOKUP(B7,unidad,3) -> CHEVROLET | E7: =VLOOKUP(B7,unidad,4) -> CELTA | F7: =VLOOKUP(B7,unidad,5) -> MEE 670 | H7: Base | J7: Base | N7: 0 | O7: =VLOOKUP(N7,estado,3) -> Seleccione Estado
A8: =+A7+1 -> 4 | B8: GDU053 | C8: =VLOOKUP(B8,unidad,2) -> Liviano | D8: =VLOOKUP(B8,unidad,3) -> FIAT | E8: =VLOOKUP(B8,unidad,4) -> FIORINO | F8: =VLOOKUP(B8,unidad,5) -> MHX 920 | H8: Base | J8: Base | N8: 0 | O8: =VLOOKUP(N8,estado,3) -> Seleccione Estado
A9: =+A8+1 -> 5 | B9: GDU061 | C9: =VLOOKUP(B9,unidad,2) -> Liviano | D9: =VLOOKUP(B9,unidad,3) -> RENAULT | E9: =VLOOKUP(B9,unidad,4) -> KANGOO | F9: =VLOOKUP(B9,unidad,5) -> AF 677 IV | H9: Base | J9: Base | N9: 0 | O9: =VLOOKUP(N9,estado,3) -> Seleccione Estado
A10: =+A9+1 -> 6 | B10: GDU055 | C10: =VLOOKUP(B10,unidad,2) -> Liviano | D10: =VLOOKUP(B10,unidad,3) -> VOLKSWAGEN | E10: =VLOOKUP(B10,unidad,4) -> AMAROK | F10: =VLOOKUP(B10,unidad,5) -> OGZ 054 | H10: Base | J10: Base | N10: 0 | O10: =VLOOKUP(N10,estado,3) -> Seleccione Estado
A11: =+A10+1 -> 7 | B11: GDU056 | C11: =VLOOKUP(B11,unidad,2) -> Liviano | D11: =VLOOKUP(B11,unidad,3) -> VOLKSWAGEN | E11: =VLOOKUP(B11,unidad,4) -> AMAROK | F11: =VLOOKUP(B11,unidad,5) -> AA 087 LA | H11: Base | J11: Base | N11: 0 | O11: =VLOOKUP(N11,estado,3) -> Seleccione Estado
A12: =+A11+1 -> 8 | B12: GDU057 | C12: =VLOOKUP(B12,unidad,2) -> Liviano | D12: =VLOOKUP(B12,unidad,3) -> VOLKSWAGEN | E12: =VLOOKUP(B12,unidad,4) -> AMAROK | F12: =VLOOKUP(B12,unidad,5) -> NZF 438 | H12: Base | J12: Base | N12: 0 | O12: =VLOOKUP(N12,estado,3) -> Seleccione Estado
A13: =+A12+1 -> 9 | B13: GDU064 | C13: =VLOOKUP(B13,unidad,2) -> Liviano | D13: =VLOOKUP(B13,unidad,3) -> FIAT | E13: =VLOOKUP(B13,unidad,4) -> STRADA | F13: =VLOOKUP(B13,unidad,5) -> AH210SR | H13: Base | J13: Base | N13: 0 | O13: =VLOOKUP(N13,estado,3) -> Seleccione Estado
A14: =+A13+1 -> 10 | B14: GDU065 | C14: =VLOOKUP(B14,unidad,2) -> Liviano | D14: =VLOOKUP(B14,unidad,3) -> FIAT | E14: =VLOOKUP(B14,unidad,4) -> FIORINO | F14: =VLOOKUP(B14,unidad,5) -> AH255OH | H14: Base | J14: Base | N14: 0 | O14: =VLOOKUP(N14,estado,3) -> Seleccione Estado
A15: =+A14+1 -> 11 | B15: GDU063 | C15: =VLOOKUP(B15,unidad,2) -> Liviano | D15: =VLOOKUP(B15,unidad,3) -> TOYOTA | E15: =VLOOKUP(B15,unidad,4) -> HILUX | F15: =VLOOKUP(B15,unidad,5) -> AD761JW | H15: Base | J15: Base | N15: 0 | O15: =VLOOKUP(N15,estado,3) -> Seleccione Estado
A16: =+A15+1 -> 12 | B16: GDU061 | C16: =VLOOKUP(B16,unidad,2) -> Liviano | D16: RENAULT | E16: KANGOO | F16: AF677IV | H16: Base | J16: Base | N16: 0 | O16: =VLOOKUP(N16,estado,3) -> Seleccione Estado
A17: =+A16+1 -> 13 | B17: GDU064 | C17: =VLOOKUP(B17,unidad,2) -> Liviano | D17: =VLOOKUP(B17,unidad,3) -> FIAT | E17: =VLOOKUP(B17,unidad,4) -> STRADA | F17: =VLOOKUP(B17,unidad,5) -> AH210SR | H17: Base | J17: Base | N17: 0 | O17: =VLOOKUP(N17,estado,3) -> Seleccione Estado
A18: =+A17+1 -> 14 | B18: GDU000 | C18: =VLOOKUP(B18,unidad,2) -> Selecciona Equipo | D18: =VLOOKUP(B18,unidad,3) -> 0 | E18: =VLOOKUP(B18,unidad,4) -> 0 | F18: =VLOOKUP(B18,unidad,5) -> 0 | H18: Base | J18: Base | N18: 0 | O18: =VLOOKUP(N18,estado,3) -> Seleccione Estado
A19: =+A18+1 -> 15 | B19: GDU000 | C19: =VLOOKUP(B19,unidad,2) -> Selecciona Equipo | D19: =VLOOKUP(B19,unidad,3) -> 0 | E19: =VLOOKUP(B19,unidad,4) -> 0 | F19: =VLOOKUP(B19,unidad,5) -> 0 | H19: Base | J19: Base | N19: 0 | O19: =VLOOKUP(N19,estado,3) -> Seleccione Estado
A20: =+A19+1 -> 16 | B20: GDU000 | C20: =VLOOKUP(B20,unidad,2) -> Selecciona Equipo | D20: =VLOOKUP(B20,unidad,3) -> 0 | E20: =VLOOKUP(B20,unidad,4) -> 0 | F20: =VLOOKUP(B20,unidad,5) -> 0 | H20: Base | J20: Base | N20: 0 | O20: =VLOOKUP(N20,estado,3) -> Seleccione Estado

Sheet Dia (4)
B1: Asignacion y uso de Vehiculos Livianos
B2: FECHA | D2: ='Dia (1)'!D2+_xlfn.SHEET()-1 -> 46269
H3: Salida | J3: Llegada
B4: Interno | D4: Tipo | E4: Marca | F4: Modelo | G4: Personal Asignado | H4: Lugar | I4: Horario | J4: Lugar | K4: Horario | L4: Uso | M4: Observaciones | N4: Estado
A5: 1 | B5: GDU001 | C5: =VLOOKUP(B5,unidad,2) -> Liviano | D5: =VLOOKUP(B5,unidad,3) -> FIAT | E5: =VLOOKUP(B5,unidad,4) -> UNO | F5: =VLOOKUP(B5,unidad,5) -> EYI 197 | G5: Salvo Jonathan Nicolas | H5: Base | I5: 0 | J5: Base | K5: 0.99930556 | N5: 0 | O5: =VLOOKUP(N5,estado,3) -> Seleccione Estado
A6: =+A5+1 -> 2 | B6: GDU002 | C6: =VLOOKUP(B6,unidad,2) -> Liviano | D6: =VLOOKUP(B6,unidad,3) -> FIAT | E6: =VLOOKUP(B6,unidad,4) -> UNO | F6: =VLOOKUP(B6,unidad,5) -> ODQ 087 | H6: Base | J6: Base | N6: 0 | O6: =VLOOKUP(N6,estado,3) -> Seleccione Estado
A7: =+A6+1 -> 3 | B7: GDU011 | C7: =VLOOKUP(B7,unidad,2) -> Liviano | D7: =VLOOKUP(B7,unidad,3) -> CHEVROLET | E7: =VLOOKUP(B7,unidad,4) -> CELTA | F7: =VLOOKUP(B7,unidad,5) -> MEE 670 | G7: Barreto Braian Jose | H7: Base | I7: 0 | J7: Base | K7: 0.99930556 | N7: 0 | O7: =VLOOKUP(N7,estado,3) -> Seleccione Estado
A8: =+A7+1 -> 4 | B8: GDU053 | C8: =VLOOKUP(B8,unidad,2) -> Liviano | D8: =VLOOKUP(B8,unidad,3) -> FIAT | E8: =VLOOKUP(B8,unidad,4) -> FIORINO | F8: =VLOOKUP(B8,unidad,5) -> MHX 920 | G8: Arocha Sergio Anibal | H8: Base | I8: 0 | J8: Base | K8: 0.99930556 | N8: 0 | O8: =VLOOKUP(N8,estado,3) -> Seleccione Estado
A9: =+A8+1 -> 5 | B9: GDU061 | C9: =VLOOKUP(B9,unidad,2) -> Liviano | D9: =VLOOKUP(B9,unidad,3) -> RENAULT | E9: =VLOOKUP(B9,unidad,4) -> KANGOO | F9: =VLOOKUP(B9,unidad,5) -> AF 677 IV | G9: Vega Jorge Luis | H9: Base | I9: 0 | J9: Base | K9: 0.99930556 | N9: 0 | O9: =VLOOKUP(N9,estado,3) -> Seleccione Estado
A10: =+A9+1 -> 6 | B10: GDU055 | C10: =VLOOKUP(B10,unidad,2) -> Liviano | D10: =VLOOKUP(B10,unidad,3) -> VOLKSWAGEN | E10: =VLOOKUP(B10,unidad,4) -> AMAROK | F10: =VLOOKUP(B10,unidad,5) -> OGZ 054 | G10: Cano Pablo Martin | H10: Base | I10: 0 | J10: Base | K10: 0.99930556 | N10: 0 | O10: =VLOOKUP(N10,estado,3) -> Seleccione Estado
A11: =+A10+1 -> 7 | B11: GDU056 | C11: =VLOOKUP(B11,unidad,2) -> Liviano | D11: =VLOOKUP(B11,unidad,3) -> VOLKSWAGEN | E11: =VLOOKUP(B11,unidad,4) -> AMAROK | F11: =VLOOKUP(B11,unidad,5) -> AA 087 LA | G11: Vazquez David Gabriel | H11: Base | I11: 0 | J11: Base | K11: 0.99930556 | N11: 0 | O11: =VLOOKUP(N11,estado,3) -> Seleccione Estado
A12: =+A11+1 -> 8 | B12: GDU057 | C12: =VLOOKUP(B12,unidad,2) -> Liviano | D12: =VLOOKUP(B12,unidad,3) -> VOLKSWAGEN | E12: =VLOOKUP(B12,unidad,4) -> AMAROK | F12: =VLOOKUP(B12,unidad,5) -> NZF 438 | G12: Gonzalez Molinas Juan Alberto | H12: Base | I12: 0 | J12: Base | K12: 0.99930556 | N12: 0 | O12: =VLOOKUP(N12,estado,3) -> Seleccione Estado
A13: =+A12+1 -> 9 | B13: GDU064 | C13: =VLOOKUP(B13,unidad,2) -> Liviano | D13: =VLOOKUP(B13,unidad,3) -> FIAT | E13: =VLOOKUP(B13,unidad,4) -> STRADA | F13: =VLOOKUP(B13,unidad,5) -> AH210SR | G13: Nappi Juan Manuel | H13: Base | I13: 0 | J13: Base | K13: 0.99930556 | N13: 0 | O13: =VLOOKUP(N13,estado,3) -> Seleccione Estado
A14: =+A13+1 -> 10 | B14: GDU065 | C14: =VLOOKUP(B14,unidad,2) -> Liviano | D14: =VLOOKUP(B14,unidad,3) -> FIAT | E14: =VLOOKUP(B14,unidad,4) -> FIORINO | F14: =VLOOKUP(B14,unidad,5) -> AH255OH | H14: Base | J14: Base | N14: 0 | O14: =VLOOKUP(N14,estado,3) -> Seleccione Estado
A15: =+A14+1 -> 11 | B15: GDU063 | C15: =VLOOKUP(B15,unidad,2) -> Liviano | D15: =VLOOKUP(B15,unidad,3) -> TOYOTA | E15: =VLOOKUP(B15,unidad,4) -> HILUX | F15: =VLOOKUP(B15,unidad,5) -> AD761JW | G15: Bordones Requena Jordan | H15: Base | J15: Base | N15: 0 | O15: =VLOOKUP(N15,estado,3) -> Seleccione Estado
A16: =+A15+1 -> 12 | B16: GDU061 | C16: =VLOOKUP(B16,unidad,2) -> Liviano | D16: RENAULT | E16: KANGOO | F16: AF677IV | H16: Base | J16: Base | N16: 0 | O16: =VLOOKUP(N16,estado,3) -> Seleccione Estado
A17: =+A16+1 -> 13 | B17: GDU064 | C17: =VLOOKUP(B17,unidad,2) -> Liviano | D17: =VLOOKUP(B17,unidad,3) -> FIAT | E17: =VLOOKUP(B17,unidad,4) -> STRADA | F17: =VLOOKUP(B17,unidad,5) -> AH210SR | H17: Base | J17: Base | N17: 0 | O17: =VLOOKUP(N17,estado,3) -> Seleccione Estado
A18: =+A17+1 -> 14 | B18: GDU000 | C18: =VLOOKUP(B18,unidad,2) -> Selecciona Equipo | D18: =VLOOKUP(B18,unidad,3) -> 0 | E18: =VLOOKUP(B18,unidad,4) -> 0 | F18: =VLOOKUP(B18,unidad,5) -> 0 | H18: Base | J18: Base | N18: 0 | O18: =VLOOKUP(N18,estado,3) -> Seleccione Estado
A19: =+A18+1 -> 15 | B19: GDU000 | C19: =VLOOKUP(B19,unidad,2) -> Selecciona Equipo | D19: =VLOOKUP(B19,unidad,3) -> 0 | E19: =VLOOKUP(B19,unidad,4) -> 0 | F19: =VLOOKUP(B19,unidad,5) -> 0 | H19: Base | J19: Base | N19: 0 | O19: =VLOOKUP(N19,estado,3) -> Seleccione Estado
A20: =+A19+1 -> 16 | B20: GDU000 | C20: =VLOOKUP(B20,unidad,2) -> Selecciona Equipo | D20: =VLOOKUP(B20,unidad,3) -> 0 | E20: =VLOOKUP(B20,unidad,4) -> 0 | F20: =VLOOKUP(B20,unidad,5) -> 0 | H20: Base | J20: Base | N20: 0 | O20: =VLOOKUP(N20,estado,3) -> Seleccione Estado

Sheet Dia (5)
B1: Asignacion y uso de Vehiculos Livianos
B2: FECHA | D2: ='Dia (1)'!D2+_xlfn.SHEET()-1 -> 46270
H3: Salida | J3: Llegada
B4: Interno | D4: Tipo | E4: Marca | F4: Modelo | G4: Personal Asignado | H4: Lugar | I4: Horario | J4: Lugar | K4: Horario | L4: Uso | M4: Observaciones | N4: Estado
A5: 1 | B5: GDU001 | C5: =VLOOKUP(B5,unidad,2) -> Liviano | D5: =VLOOKUP(B5,unidad,3) -> FIAT | E5: =VLOOKUP(B5,unidad,4) -> UNO | F5: =VLOOKUP(B5,unidad,5) -> EYI 197 | G5: Salvo Jonathan Nicolas | H5: Base | I5: 0 | J5: Base | K5: 0.99930556 | N5: 0 | O5: =VLOOKUP(N5,estado,3) -> Seleccione Estado
A6: =+A5+1 -> 2 | B6: GDU002 | C6: =VLOOKUP(B6,unidad,2) -> Liviano | D6: =VLOOKUP(B6,unidad,3) -> FIAT | E6: =VLOOKUP(B6,unidad,4) -> UNO | F6: =VLOOKUP(B6,unidad,5) -> ODQ 087 | G6: Campos Fernandez Jose Antonio | H6: Base | I6: 0 | J6: Base | K6: 0.99930556 | N6: 0 | O6: =VLOOKUP(N6,estado,3) -> Seleccione Estado
A7: =+A6+1 -> 3 | B7: GDU011 | C7: =VLOOKUP(B7,unidad,2) -> Liviano | D7: =VLOOKUP(B7,unidad,3) -> CHEVROLET | E7: =VLOOKUP(B7,unidad,4) -> CELTA | F7: =VLOOKUP(B7,unidad,5) -> MEE 670 | G7: Barreto Braian Jose | H7: Base | I7: 0 | J7: Base | K7: 0.99930556 | N7: 0 | O7: =VLOOKUP(N7,estado,3) -> Seleccione Estado
A8: =+A7+1 -> 4 | B8: GDU053 | C8: =VLOOKUP(B8,unidad,2) -> Liviano | D8: =VLOOKUP(B8,unidad,3) -> FIAT | E8: =VLOOKUP(B8,unidad,4) -> FIORINO | F8: =VLOOKUP(B8,unidad,5) -> MHX 920 | G8: Arocha Sergio Anibal | H8: Base | I8: 0 | J8: Base | K8: 0.99930556 | N8: 0 | O8: =VLOOKUP(N8,estado,3) -> Seleccione Estado
A9: =+A8+1 -> 5 | B9: GDU061 | C9: =VLOOKUP(B9,unidad,2) -> Liviano | D9: =VLOOKUP(B9,unidad,3) -> RENAULT | E9: =VLOOKUP(B9,unidad,4) -> KANGOO | F9: =VLOOKUP(B9,unidad,5) -> AF 677 IV | G9: Vega Jorge Luis | H9: Base | I9: 0 | J9: Base | K9: 0.99930556 | N9: 0 | O9: =VLOOKUP(N9,estado,3) -> Seleccione Estado
A10: =+A9+1 -> 6 | B10: GDU055 | C10: =VLOOKUP(B10,unidad,2) -> Liviano | D10: =VLOOKUP(B10,unidad,3) -> VOLKSWAGEN | E10: =VLOOKUP(B10,unidad,4) -> AMAROK | F10: =VLOOKUP(B10,unidad,5) -> OGZ 054 | G10: Cano Pablo Martin | H10: Base | I10: 0 | J10: Base | K10: 0.99930556 | N10: 0 | O10: =VLOOKUP(N10,estado,3) -> Seleccione Estado
A11: =+A10+1 -> 7 | B11: GDU056 | C11: =VLOOKUP(B11,unidad,2) -> Liviano | D11: =VLOOKUP(B11,unidad,3) -> VOLKSWAGEN | E11: =VLOOKUP(B11,unidad,4) -> AMAROK | F11: =VLOOKUP(B11,unidad,5) -> AA 087 LA | G11: Vazquez David Gabriel | H11: Base | I11: 0 | J11: Base | K11: 0.99930556 | N11: 0 | O11: =VLOOKUP(N11,estado,3) -> Seleccione Estado
A12: =+A11+1 -> 8 | B12: GDU057 | C12: =VLOOKUP(B12,unidad,2) -> Liviano | D12: =VLOOKUP(B12,unidad,3) -> VOLKSWAGEN | E12: =VLOOKUP(B12,unidad,4) -> AMAROK | F12: =VLOOKUP(B12,unidad,5) -> NZF 438 | G12: Gonzalez Molinas Juan Alberto | H12: Base | I12: 0 | J12: Base | K12: 0.99930556 | N12: 0 | O12: =VLOOKUP(N12,estado,3) -> Seleccione Estado
A13: =+A12+1 -> 9 | B13: GDU064 | C13: =VLOOKUP(B13,unidad,2) -> Liviano | D13: =VLOOKUP(B13,unidad,3) -> FIAT | E13: =VLOOKUP(B13,unidad,4) -> STRADA | F13: =VLOOKUP(B13,unidad,5) -> AH210SR | G13: Nappi Juan Manuel | H13: Base | I13: 0 | J13: Base | K13: 0.99930556 | N13: 0 | O13: =VLOOKUP(N13,estado,3) -> Seleccione Estado
A14: =+A13+1 -> 10 | B14: GDU065 | C14: =VLOOKUP(B14,unidad,2) -> Liviano | D14: =VLOOKUP(B14,unidad,3) -> FIAT | E14: =VLOOKUP(B14,unidad,4) -> FIORINO | F14: =VLOOKUP(B14,unidad,5) -> AH255OH | H14: Base | J14: Base | N14: 0 | O14: =VLOOKUP(N14,estado,3) -> Seleccione Estado
A15: =+A14+1 -> 11 | B15: GDU063 | C15: =VLOOKUP(B15,unidad,2) -> Liviano | D15: =VLOOKUP(B15,unidad,3) -> TOYOTA | E15: =VLOOKUP(B15,unidad,4) -> HILUX | F15: =VLOOKUP(B15,unidad,5) -> AD761JW | H15: Base | J15: Base | N15: 0 | O15: =VLOOKUP(N15,estado,3) -> Seleccione Estado
A16: =+A15+1 -> 12 | B16: GDU061 | C16: =VLOOKUP(B16,unidad,2) -> Liviano | D16: RENAULT | E16: KANGOO | F16: AF677IV | H16: Base | J16: Base | N16: 0 | O16: =VLOOKUP(N16,estado,3) -> Seleccione Estado
A17: =+A16+1 -> 13 | B17: GDU064 | C17: =VLOOKUP(B17,unidad,2) -> Liviano | D17: =VLOOKUP(B17,unidad,3) -> FIAT | E17: =VLOOKUP(B17,unidad,4) -> STRADA | F17: =VLOOKUP(B17,unidad,5) -> AH210SR | H17: Base | J17: Base | N17: 0 | O17: =VLOOKUP(N17,estado,3) -> Seleccione Estado
A18: =+A17+1 -> 14 | B18: GDU000 | C18: =VLOOKUP(B18,unidad,2) -> Selecciona Equipo | D18: =VLOOKUP(B18,unidad,3) -> 0 | E18: =VLOOKUP(B18,unidad,4) -> 0 | F18: =VLOOKUP(B18,unidad,5) -> 0 | H18: Base | J18: Base | N18: 0 | O18: =VLOOKUP(N18,estado,3) -> Seleccione Estado
A19: =+A18+1 -> 15 | B19: GDU000 | C19: =VLOOKUP(B19,unidad,2) -> Selecciona Equipo | D19: =VLOOKUP(B19,unidad,3) -> 0 | E19: =VLOOKUP(B19,unidad,4) -> 0 | F19: =VLOOKUP(B19,unidad,5) -> 0 | H19: Base | J19: Base | N19: 0 | O19: =VLOOKUP(N19,estado,3) -> Seleccione Estado
A20: =+A19+1 -> 16 | B20: GDU000 | C20: =VLOOKUP(B20,unidad,2) -> Selecciona Equipo | D20: =VLOOKUP(B20,unidad,3) -> 0 | E20: =VLOOKUP(B20,unidad,4) -> 0 | F20: =VLOOKUP(B20,unidad,5) -> 0 | H20: Base | J20: Base | N20: 0 | O20: =VLOOKUP(N20,estado,3) -> Seleccione Estado

Sheet Dia (6)
B1: Asignacion y uso de Vehiculos Livianos
B2: FECHA | D2: ='Dia (1)'!D2+_xlfn.SHEET()-1 -> 46271
H3: Salida | J3: Llegada
B4: Interno | D4: Tipo | E4: Marca | F4: Modelo | G4: Personal Asignado | H4: Lugar | I4: Horario | J4: Lugar | K4: Horario | L4: Uso | M4: Observaciones | N4: Estado
A5: 1 | B5: GDU001 | C5: =VLOOKUP(B5,unidad,2) -> Liviano | D5: =VLOOKUP(B5,unidad,3) -> FIAT | E5: =VLOOKUP(B5,unidad,4) -> UNO | F5: =VLOOKUP(B5,unidad,5) -> EYI 197 | G5: Salvo Jonathan Nicolas | H5: Base | I5: 0 | J5: Base | K5: 0.99930556 | N5: 0 | O5: =VLOOKUP(N5,estado,3) -> Seleccione Estado
A6: =+A5+1 -> 2 | B6: GDU002 | C6: =VLOOKUP(B6,unidad,2) -> Liviano | D6: =VLOOKUP(B6,unidad,3) -> FIAT | E6: =VLOOKUP(B6,unidad,4) -> UNO | F6: =VLOOKUP(B6,unidad,5) -> ODQ 087 | G6: Acosta Daniel Horacio | H6: Base | I6: 0.5 | J6: Base | K6: 0.99930556 | N6: 0 | O6: =VLOOKUP(N6,estado,3) -> Seleccione Estado
A7: =+A6+1 -> 3 | B7: GDU011 | C7: =VLOOKUP(B7,unidad,2) -> Liviano | D7: =VLOOKUP(B7,unidad,3) -> CHEVROLET | E7: =VLOOKUP(B7,unidad,4) -> CELTA | F7: =VLOOKUP(B7,unidad,5) -> MEE 670 | G7: Barreto Braian Jose | H7: Base | I7: 0 | J7: Base | K7: 0.99930556 | N7: 0 | O7: =VLOOKUP(N7,estado,3) -> Seleccione Estado
A8: =+A7+1 -> 4 | B8: GDU053 | C8: =VLOOKUP(B8,unidad,2) -> Liviano | D8: =VLOOKUP(B8,unidad,3) -> FIAT | E8: =VLOOKUP(B8,unidad,4) -> FIORINO | F8: =VLOOKUP(B8,unidad,5) -> MHX 920 | G8: Arocha Sergio Anibal | H8: Base | I8: 0 | J8: Base | K8: 0.99930556 | N8: 0 | O8: =VLOOKUP(N8,estado,3) -> Seleccione Estado
A9: =+A8+1 -> 5 | B9: GDU061 | C9: =VLOOKUP(B9,unidad,2) -> Liviano | D9: =VLOOKUP(B9,unidad,3) -> RENAULT | E9: =VLOOKUP(B9,unidad,4) -> KANGOO | F9: =VLOOKUP(B9,unidad,5) -> AF 677 IV | G9: Vega Jorge Luis | H9: Base | I9: 0 | J9: Base | K9: 0.99930556 | N9: 0 | O9: =VLOOKUP(N9,estado,3) -> Seleccione Estado
A10: =+A9+1 -> 6 | B10: GDU055 | C10: =VLOOKUP(B10,unidad,2) -> Liviano | D10: =VLOOKUP(B10,unidad,3) -> VOLKSWAGEN | E10: =VLOOKUP(B10,unidad,4) -> AMAROK | F10: =VLOOKUP(B10,unidad,5) -> OGZ 054 | G10: Cano Pablo Martin | H10: Base | I10: 0 | J10: Base | K10: 0.99930556 | N10: 0 | O10: =VLOOKUP(N10,estado,3) -> Seleccione Estado
A11: =+A10+1 -> 7 | B11: GDU056 | C11: =VLOOKUP(B11,unidad,2) -> Liviano | D11: =VLOOKUP(B11,unidad,3) -> VOLKSWAGEN | E11: =VLOOKUP(B11,unidad,4) -> AMAROK | F11: =VLOOKUP(B11,unidad,5) -> AA 087 LA | G11: Vazquez David Gabriel | H11: Base | I11: 0 | J11: Base | K11: 0.99930556 | N11: 0 | O11: =VLOOKUP(N11,estado,3) -> Seleccione Estado
A12: =+A11+1 -> 8 | B12: GDU057 | C12: =VLOOKUP(B12,unidad,2) -> Liviano | D12: =VLOOKUP(B12,unidad,3) -> VOLKSWAGEN | E12: =VLOOKUP(B12,unidad,4) -> AMAROK | F12: =VLOOKUP(B12,unidad,5) -> NZF 438 | G12: Gonzalez Molinas Juan Alberto | H12: Base | I12: 0 | J12: Base | K12: 0.99930556 | N12: 0 | O12: =VLOOKUP(N12,estado,3) -> Seleccione Estado
A13: =+A12+1 -> 9 | B13: GDU064 | C13: =VLOOKUP(B13,unidad,2) -> Liviano | D13: =VLOOKUP(B13,unidad,3) -> FIAT | E13: =VLOOKUP(B13,unidad,4) -> STRADA | F13: =VLOOKUP(B13,unidad,5) -> AH210SR | G13: Nappi Juan Manuel | H13: Base | I13: 0 | J13: Base | K13: 0.99930556 | N13: 0 | O13: =VLOOKUP(N13,estado,3) -> Seleccione Estado
A14: =+A13+1 -> 10 | B14: GDU065 | C14: =VLOOKUP(B14,unidad,2) -> Liviano | D14: =VLOOKUP(B14,unidad,3) -> FIAT | E14: =VLOOKUP(B14,unidad,4) -> FIORINO | F14: =VLOOKUP(B14,unidad,5) -> AH255OH | H14: Base | J14: Base | N14: 0 | O14: =VLOOKUP(N14,estado,3) -> Seleccione Estado
A15: =+A14+1 -> 11 | B15: GDU063 | C15: =VLOOKUP(B15,unidad,2) -> Liviano | D15: =VLOOKUP(B15,unidad,3) -> TOYOTA | E15: =VLOOKUP(B15,unidad,4) -> HILUX | F15: =VLOOKUP(B15,unidad,5) -> AD761JW | H15: Base | J15: Base | N15: 0 | O15: =VLOOKUP(N15,estado,3) -> Seleccione Estado
A16: =+A15+1 -> 12 | B16: GDU061 | C16: =VLOOKUP(B16,unidad,2) -> Liviano | D16: RENAULT | E16: KANGOO | F16: AF677IV | H16: Base | J16: Base | N16: 0 | O16: =VLOOKUP(N16,estado,3) -> Seleccione Estado
A17: =+A16+1 -> 13 | B17: GDU064 | C17: =VLOOKUP(B17,unidad,2) -> Liviano | D17: =VLOOKUP(B17,unidad,3) -> FIAT | E17: =VLOOKUP(B17,unidad,4) -> STRADA | F17: =VLOOKUP(B17,unidad,5) -> AH210SR | H17: Base | J17: Base | N17: 0 | O17: =VLOOKUP(N17,estado,3) -> Seleccione Estado
A18: =+A17+1 -> 14 | B18: GDU000 | C18: =VLOOKUP(B18,unidad,2) -> Selecciona Equipo | D18: =VLOOKUP(B18,unidad,3) -> 0 | E18: =VLOOKUP(B18,unidad,4) -> 0 | F18: =VLOOKUP(B18,unidad,5) -> 0 | H18: Base | J18: Base | N18: 0 | O18: =VLOOKUP(N18,estado,3) -> Seleccione Estado
A19: =+A18+1 -> 15 | B19: GDU000 | C19: =VLOOKUP(B19,unidad,2) -> Selecciona Equipo | D19: =VLOOKUP(B19,unidad,3) -> 0 | E19: =VLOOKUP(B19,unidad,4) -> 0 | F19: =VLOOKUP(B19,unidad,5) -> 0 | H19: Base | J19: Base | N19: 0 | O19: =VLOOKUP(N19,estado,3) -> Seleccione Estado
A20: =+A19+1 -> 16 | B20: GDU000 | C20: =VLOOKUP(B20,unidad,2) -> Selecciona Equipo | D20: =VLOOKUP(B20,unidad,3) -> 0 | E20: =VLOOKUP(B20,unidad,4) -> 0 | F20: =VLOOKUP(B20,unidad,5) -> 0 | H20: Base | J20: Base | N20: 0 | O20: =VLOOKUP(N20,estado,3) -> Seleccione Estado

Sheet Dia (7)
B1: Asignacion y uso de Vehiculos Livianos
B2: FECHA | D2: ='Dia (1)'!D2+_xlfn.SHEET()-1 -> 46272
H3: Salida | J3: Llegada
B4: Interno | D4: Tipo | E4: Marca | F4: Modelo | G4: Personal Asignado | H4: Lugar | I4: Horario | J4: Lugar | K4: Horario | L4: Uso | M4: Observaciones | N4: Estado
A5: 1 | B5: GDU001 | C5: =VLOOKUP(B5,unidad,2) -> Liviano | D5: =VLOOKUP(B5,unidad,3) -> FIAT | E5: =VLOOKUP(B5,unidad,4) -> UNO | F5: =VLOOKUP(B5,unidad,5) -> EYI 197 | G5: Salvo Jonathan Nicolas | H5: Base | I5: 0 | J5: Base | K5: 0.99930556 | N5: 0 | O5: =VLOOKUP(N5,estado,3) -> Seleccione Estado
A6: =+A5+1 -> 2 | B6: GDU002 | C6: =VLOOKUP(B6,unidad,2) -> Liviano | D6: =VLOOKUP(B6,unidad,3) -> FIAT | E6: =VLOOKUP(B6,unidad,4) -> UNO | F6: =VLOOKUP(B6,unidad,5) -> ODQ 087 | H6: Base | J6: Base | N6: 0 | O6: =VLOOKUP(N6,estado,3) -> Seleccione Estado
A7: =+A6+1 -> 3 | B7: GDU011 | C7: =VLOOKUP(B7,unidad,2) -> Liviano | D7: =VLOOKUP(B7,unidad,3) -> CHEVROLET | E7: =VLOOKUP(B7,unidad,4) -> CELTA | F7: =VLOOKUP(B7,unidad,5) -> MEE 670 | G7: Barreto Braian Jose | H7: Base | I7: 0 | J7: Base | K7: 0.99930556 | N7: 0 | O7: =VLOOKUP(N7,estado,3) -> Seleccione Estado
A8: =+A7+1 -> 4 | B8: GDU053 | C8: =VLOOKUP(B8,unidad,2) -> Liviano | D8: =VLOOKUP(B8,unidad,3) -> FIAT | E8: =VLOOKUP(B8,unidad,4) -> FIORINO | F8: =VLOOKUP(B8,unidad,5) -> MHX 920 | G8: Arocha Sergio Anibal | H8: Base | I8: 0 | J8: Base | K8: 0.99930556 | N8: 0 | O8: =VLOOKUP(N8,estado,3) -> Seleccione Estado
A9: =+A8+1 -> 5 | B9: GDU061 | C9: =VLOOKUP(B9,unidad,2) -> Liviano | D9: =VLOOKUP(B9,unidad,3) -> RENAULT | E9: =VLOOKUP(B9,unidad,4) -> KANGOO | F9: =VLOOKUP(B9,unidad,5) -> AF 677 IV | G9: Vega Jorge Luis | H9: Base | I9: 0 | J9: Base | K9: 0.99930556 | N9: 0 | O9: =VLOOKUP(N9,estado,3) -> Seleccione Estado
A10: =+A9+1 -> 6 | B10: GDU055 | C10: =VLOOKUP(B10,unidad,2) -> Liviano | D10: =VLOOKUP(B10,unidad,3) -> VOLKSWAGEN | E10: =VLOOKUP(B10,unidad,4) -> AMAROK | F10: =VLOOKUP(B10,unidad,5) -> OGZ 054 | G10: Jimenez Manuel Ernesto | H10: Base | I10: 0.625 | J10: Base | K10: 0.95833333 | N10: 0 | O10: =VLOOKUP(N10,estado,3) -> Seleccione Estado
A11: =+A10+1 -> 7 | B11: GDU056 | C11: =VLOOKUP(B11,unidad,2) -> Liviano | D11: =VLOOKUP(B11,unidad,3) -> VOLKSWAGEN | E11: =VLOOKUP(B11,unidad,4) -> AMAROK | F11: =VLOOKUP(B11,unidad,5) -> AA 087 LA | G11: Vazquez David Gabriel | H11: Base | I11: 0 | J11: Base | K11: 0.99930556 | N11: 0 | O11: =VLOOKUP(N11,estado,3) -> Seleccione Estado
A12: =+A11+1 -> 8 | B12: GDU057 | C12: =VLOOKUP(B12,unidad,2) -> Liviano | D12: =VLOOKUP(B12,unidad,3) -> VOLKSWAGEN | E12: =VLOOKUP(B12,unidad,4) -> AMAROK | F12: =VLOOKUP(B12,unidad,5) -> NZF 438 | G12: Gonzalez Molinas Juan Alberto | H12: Base | I12: 0 | J12: Base | K12: 0.99930556 | N12: 0 | O12: =VLOOKUP(N12,estado,3) -> Seleccione Estado
A13: =+A12+1 -> 9 | B13: GDU064 | C13: =VLOOKUP(B13,unidad,2) -> Liviano | D13: =VLOOKUP(B13,unidad,3) -> FIAT | E13: =VLOOKUP(B13,unidad,4) -> STRADA | F13: =VLOOKUP(B13,unidad,5) -> AH210SR | G13: Nappi Juan Manuel | H13: Base | I13: 0 | J13: Base | K13: 0.99930556 | N13: 0 | O13: =VLOOKUP(N13,estado,3) -> Seleccione Estado
A14: =+A13+1 -> 10 | B14: GDU065 | C14: =VLOOKUP(B14,unidad,2) -> Liviano | D14: =VLOOKUP(B14,unidad,3) -> FIAT | E14: =VLOOKUP(B14,unidad,4) -> FIORINO | F14: =VLOOKUP(B14,unidad,5) -> AH255OH | H14: Base | J14: Base | N14: 0 | O14: =VLOOKUP(N14,estado,3) -> Seleccione Estado
A15: =+A14+1 -> 11 | B15: GDU063 | C15: =VLOOKUP(B15,unidad,2) -> Liviano | D15: =VLOOKUP(B15,unidad,3) -> TOYOTA | E15: =VLOOKUP(B15,unidad,4) -> HILUX | F15: =VLOOKUP(B15,unidad,5) -> AD761JW | H15: Base | J15: Base | N15: 0 | O15: =VLOOKUP(N15,estado,3) -> Seleccione Estado
A16: =+A15+1 -> 12 | B16: GDU061 | C16: =VLOOKUP(B16,unidad,2) -> Liviano | D16: RENAULT | E16: KANGOO | F16: AF677IV | H16: Base | J16: Base | N16: 0 | O16: =VLOOKUP(N16,estado,3) -> Seleccione Estado
A17: =+A16+1 -> 13 | B17: GDU064 | C17: =VLOOKUP(B17,unidad,2) -> Liviano | D17: =VLOOKUP(B17,unidad,3) -> FIAT | E17: =VLOOKUP(B17,unidad,4) -> STRADA | F17: =VLOOKUP(B17,unidad,5) -> AH210SR | H17: Base | J17: Base | N17: 0 | O17: =VLOOKUP(N17,estado,3) -> Seleccione Estado
A18: =+A17+1 -> 14 | B18: GDU000 | C18: =VLOOKUP(B18,unidad,2) -> Selecciona Equipo | D18: =VLOOKUP(B18,unidad,3) -> 0 | E18: =VLOOKUP(B18,unidad,4) -> 0 | F18: =VLOOKUP(B18,unidad,5) -> 0 | H18: Base | J18: Base | N18: 0 | O18: =VLOOKUP(N18,estado,3) -> Seleccione Estado
A19: =+A18+1 -> 15 | B19: GDU000 | C19: =VLOOKUP(B19,unidad,2) -> Selecciona Equipo | D19: =VLOOKUP(B19,unidad,3) -> 0 | E19: =VLOOKUP(B19,unidad,4) -> 0 | F19: =VLOOKUP(B19,unidad,5) -> 0 | H19: Base | J19: Base | N19: 0 | O19: =VLOOKUP(N19,estado,3) -> Seleccione Estado
A20: =+A19+1 -> 16 | B20: GDU000 | C20: =VLOOKUP(B20,unidad,2) -> Selecciona Equipo | D20: =VLOOKUP(B20,unidad,3) -> 0 | E20: =VLOOKUP(B20,unidad,4) -> 0 | F20: =VLOOKUP(B20,unidad,5) -> 0 | H20: Base | J20: Base | N20: 0 | O20: =VLOOKUP(N20,estado,3) -> Seleccione Estado

Sheet Dia (8)
B1: Asignacion y uso de Vehiculos Livianos
B2: FECHA | D2: ='Dia (1)'!D2+_xlfn.SHEET()-1 -> 46273
H3: Salida | J3: Llegada
B4: Interno | D4: Tipo | E4: Marca | F4: Modelo | G4: Personal Asignado | H4: Lugar | I4: Horario | J4: Lugar | K4: Horario | L4: Uso | M4: Observaciones | N4: Estado
A5: 1 | B5: GDU001 | C5: =VLOOKUP(B5,unidad,2) -> Liviano | D5: =VLOOKUP(B5,unidad,3) -> FIAT | E5: =VLOOKUP(B5,unidad,4) -> UNO | F5: =VLOOKUP(B5,unidad,5) -> EYI 197 | G5: Salvo Jonathan Nicolas | H5: Base | I5: 0 | J5: Base | K5: 0.99930556 | N5: 0 | O5: =VLOOKUP(N5,estado,3) -> Seleccione Estado
A6: =+A5+1 -> 2 | B6: GDU002 | C6: =VLOOKUP(B6,unidad,2) -> Liviano | D6: =VLOOKUP(B6,unidad,3) -> FIAT | E6: =VLOOKUP(B6,unidad,4) -> UNO | F6: =VLOOKUP(B6,unidad,5) -> ODQ 087 | G6: Nappi Kevin Ezequiel | H6: Base | I6: 0.29166667 | J6: Base | N6: 0 | O6: =VLOOKUP(N6,estado,3) -> Seleccione Estado
A7: =+A6+1 -> 3 | B7: GDU011 | C7: =VLOOKUP(B7,unidad,2) -> Liviano | D7: =VLOOKUP(B7,unidad,3) -> CHEVROLET | E7: =VLOOKUP(B7,unidad,4) -> CELTA | F7: =VLOOKUP(B7,unidad,5) -> MEE 670 | G7: Barreto Braian Jose | H7: Base | I7: 0 | J7: Base | K7: 0.99930556 | N7: 0 | O7: =VLOOKUP(N7,estado,3) -> Seleccione Estado
A8: =+A7+1 -> 4 | B8: GDU053 | C8: =VLOOKUP(B8,unidad,2) -> Liviano | D8: =VLOOKUP(B8,unidad,3) -> FIAT | E8: =VLOOKUP(B8,unidad,4) -> FIORINO | F8: =VLOOKUP(B8,unidad,5) -> MHX 920 | G8: Arocha Sergio Anibal | H8: Base | I8: 0 | J8: Base | K8: 0.99930556 | N8: 0 | O8: =VLOOKUP(N8,estado,3) -> Seleccione Estado
A9: =+A8+1 -> 5 | B9: GDU061 | C9: =VLOOKUP(B9,unidad,2) -> Liviano | D9: =VLOOKUP(B9,unidad,3) -> RENAULT | E9: =VLOOKUP(B9,unidad,4) -> KANGOO | F9: =VLOOKUP(B9,unidad,5) -> AF 677 IV | G9: Vega Jorge Luis | H9: Base | I9: 0 | J9: Base | K9: 0.99930556 | N9: 0 | O9: =VLOOKUP(N9,estado,3) -> Seleccione Estado
A10: =+A9+1 -> 6 | B10: GDU055 | C10: =VLOOKUP(B10,unidad,2) -> Liviano | D10: =VLOOKUP(B10,unidad,3) -> VOLKSWAGEN | E10: =VLOOKUP(B10,unidad,4) -> AMAROK | F10: =VLOOKUP(B10,unidad,5) -> OGZ 054 | H10: Base | J10: Base | L10: CRISTOFER PABLO | N10: 0 | O10: =VLOOKUP(N10,estado,3) -> Seleccione Estado
A11: =+A10+1 -> 7 | B11: GDU056 | C11: =VLOOKUP(B11,unidad,2) -> Liviano | D11: =VLOOKUP(B11,unidad,3) -> VOLKSWAGEN | E11: =VLOOKUP(B11,unidad,4) -> AMAROK | F11: =VLOOKUP(B11,unidad,5) -> AA 087 LA | G11: Vazquez David Gabriel | H11: Base | I11: 0 | J11: Base | K11: 0.99930556 | N11: 0 | O11: =VLOOKUP(N11,estado,3) -> Seleccione Estado
A12: =+A11+1 -> 8 | B12: GDU057 | C12: =VLOOKUP(B12,unidad,2) -> Liviano | D12: =VLOOKUP(B12,unidad,3) -> VOLKSWAGEN | E12: =VLOOKUP(B12,unidad,4) -> AMAROK | F12: =VLOOKUP(B12,unidad,5) -> NZF 438 | G12: Gonzalez Molinas Juan Alberto | H12: Base | I12: 0 | J12: Base | K12: 0.99930556 | N12: 0 | O12: =VLOOKUP(N12,estado,3) -> Seleccione Estado
A13: =+A12+1 -> 9 | B13: GDU064 | C13: =VLOOKUP(B13,unidad,2) -> Liviano | D13: =VLOOKUP(B13,unidad,3) -> FIAT | E13: =VLOOKUP(B13,unidad,4) -> STRADA | F13: =VLOOKUP(B13,unidad,5) -> AH210SR | G13: Nappi Juan Manuel | H13: Base | I13: 0 | J13: Base | K13: 0.99930556 | N13: 0 | O13: =VLOOKUP(N13,estado,3) -> Seleccione Estado
A14: =+A13+1 -> 10 | B14: GDU065 | C14: =VLOOKUP(B14,unidad,2) -> Liviano | D14: =VLOOKUP(B14,unidad,3) -> FIAT | E14: =VLOOKUP(B14,unidad,4) -> FIORINO | F14: =VLOOKUP(B14,unidad,5) -> AH255OH | H14: Base | J14: Base | N14: 0 | O14: =VLOOKUP(N14,estado,3) -> Seleccione Estado
A15: =+A14+1 -> 11 | B15: GDU063 | C15: =VLOOKUP(B15,unidad,2) -> Liviano | D15: =VLOOKUP(B15,unidad,3) -> TOYOTA | E15: =VLOOKUP(B15,unidad,4) -> HILUX | F15: =VLOOKUP(B15,unidad,5) -> AD761JW | H15: Base | J15: Base | L15: EHINGEN | N15: 0 | O15: =VLOOKUP(N15,estado,3) -> Seleccione Estado
A16: =+A15+1 -> 12 | B16: GDU061 | C16: =VLOOKUP(B16,unidad,2) -> Liviano | D16: RENAULT | E16: KANGOO | F16: AF677IV | H16: Base | J16: Base | N16: 0 | O16: =VLOOKUP(N16,estado,3) -> Seleccione Estado
A17: =+A16+1 -> 13 | B17: GDU064 | C17: =VLOOKUP(B17,unidad,2) -> Liviano | D17: =VLOOKUP(B17,unidad,3) -> FIAT | E17: =VLOOKUP(B17,unidad,4) -> STRADA | F17: =VLOOKUP(B17,unidad,5) -> AH210SR | H17: Base | J17: Base | N17: 0 | O17: =VLOOKUP(N17,estado,3) -> Seleccione Estado
A18: =+A17+1 -> 14 | B18: GDU000 | C18: =VLOOKUP(B18,unidad,2) -> Selecciona Equipo | D18: =VLOOKUP(B18,unidad,3) -> 0 | E18: =VLOOKUP(B18,unidad,4) -> 0 | F18: =VLOOKUP(B18,unidad,5) -> 0 | H18: Base | J18: Base | N18: 0 | O18: =VLOOKUP(N18,estado,3) -> Seleccione Estado
A19: =+A18+1 -> 15 | B19: GDU000 | C19: =VLOOKUP(B19,unidad,2) -> Selecciona Equipo | D19: =VLOOKUP(B19,unidad,3) -> 0 | E19: =VLOOKUP(B19,unidad,4) -> 0 | F19: =VLOOKUP(B19,unidad,5) -> 0 | H19: Base | J19: Base | N19: 0 | O19: =VLOOKUP(N19,estado,3) -> Seleccione Estado
A20: =+A19+1 -> 16 | B20: GDU000 | C20: =VLOOKUP(B20,unidad,2) -> Selecciona Equipo | D20: =VLOOKUP(B20,unidad,3) -> 0 | E20: =VLOOKUP(B20,unidad,4) -> 0 | F20: =VLOOKUP(B20,unidad,5) -> 0 | H20: Base | J20: Base | N20: 0 | O20: =VLOOKUP(N20,estado,3) -> Seleccione Estado

Sheet Dia (9)
B1: Asignacion y uso de Vehiculos Livianos
B2: FECHA | D2: ='Dia (1)'!D2+_xlfn.SHEET()-1 -> 46274
H3: Salida | J3: Llegada
B4: Interno | D4: Tipo | E4: Marca | F4: Modelo | G4: Personal Asignado | H4: Lugar | I4: Horario | J4: Lugar | K4: Horario | L4: Uso | M4: Observaciones | N4: Estado
A5: 1 | B5: GDU001 | C5: =VLOOKUP(B5,unidad,2) -> Liviano | D5: =VLOOKUP(B5,unidad,3) -> FIAT | E5: =VLOOKUP(B5,unidad,4) -> UNO | F5: =VLOOKUP(B5,unidad,5) -> EYI 197 | G5: Salvo Jonathan Nicolas | H5: Base | I5: 0 | J5: Base | K5: 0.99930556 | N5: 0 | O5: =VLOOKUP(N5,estado,3) -> Seleccione Estado
A6: =+A5+1 -> 2 | B6: GDU002 | C6: =VLOOKUP(B6,unidad,2) -> Liviano | D6: =VLOOKUP(B6,unidad,3) -> FIAT | E6: =VLOOKUP(B6,unidad,4) -> UNO | F6: =VLOOKUP(B6,unidad,5) -> ODQ 087 | H6: Base | J6: Base | N6: 0 | O6: =VLOOKUP(N6,estado,3) -> Seleccione Estado
A7: =+A6+1 -> 3 | B7: GDU011 | C7: =VLOOKUP(B7,unidad,2) -> Liviano | D7: =VLOOKUP(B7,unidad,3) -> CHEVROLET | E7: =VLOOKUP(B7,unidad,4) -> CELTA | F7: =VLOOKUP(B7,unidad,5) -> MEE 670 | G7: Barreto Braian Jose | H7: Base | I7: 0 | J7: Base | K7: 0.99930556 | N7: 0 | O7: =VLOOKUP(N7,estado,3) -> Seleccione Estado
A8: =+A7+1 -> 4 | B8: GDU053 | C8: =VLOOKUP(B8,unidad,2) -> Liviano | D8: =VLOOKUP(B8,unidad,3) -> FIAT | E8: =VLOOKUP(B8,unidad,4) -> FIORINO | F8: =VLOOKUP(B8,unidad,5) -> MHX 920 | G8: Arocha Sergio Anibal | H8: Base | I8: 0 | J8: Base | K8: 0.96180556 | N8: 0 | O8: =VLOOKUP(N8,estado,3) -> Seleccione Estado
A9: =+A8+1 -> 5 | B9: GDU061 | C9: =VLOOKUP(B9,unidad,2) -> Liviano | D9: =VLOOKUP(B9,unidad,3) -> RENAULT | E9: =VLOOKUP(B9,unidad,4) -> KANGOO | F9: =VLOOKUP(B9,unidad,5) -> AF 677 IV | G9: Vega Jorge Luis | H9: Base | I9: 2 | J9: Base | K9: 0.99930556 | N9: 0 | O9: =VLOOKUP(N9,estado,3) -> Seleccione Estado
A10: =+A9+1 -> 6 | B10: GDU055 | C10: =VLOOKUP(B10,unidad,2) -> Liviano | D10: =VLOOKUP(B10,unidad,3) -> VOLKSWAGEN | E10: =VLOOKUP(B10,unidad,4) -> AMAROK | F10: =VLOOKUP(B10,unidad,5) -> OGZ 054 | H10: Base | I10: 0 | J10: Base | N10: 0 | O10: =VLOOKUP(N10,estado,3) -> Seleccione Estado
A11: =+A10+1 -> 7 | B11: GDU056 | C11: =VLOOKUP(B11,unidad,2) -> Liviano | D11: =VLOOKUP(B11,unidad,3) -> VOLKSWAGEN | E11: =VLOOKUP(B11,unidad,4) -> AMAROK | F11: =VLOOKUP(B11,unidad,5) -> AA 087 LA | G11: Vazquez David Gabriel | H11: Base | I11: 0 | J11: Base | K11: 0.99930556 | N11: 0 | O11: =VLOOKUP(N11,estado,3) -> Seleccione Estado
A12: =+A11+1 -> 8 | B12: GDU057 | C12: =VLOOKUP(B12,unidad,2) -> Liviano | D12: =VLOOKUP(B12,unidad,3) -> VOLKSWAGEN | E12: =VLOOKUP(B12,unidad,4) -> AMAROK | F12: =VLOOKUP(B12,unidad,5) -> NZF 438 | G12: Gonzalez Molinas Juan Alberto | H12: Base | I12: 0 | J12: Base | K12: 0.99930556 | N12: 0 | O12: =VLOOKUP(N12,estado,3) -> Seleccione Estado
A13: =+A12+1 -> 9 | B13: GDU064 | C13: =VLOOKUP(B13,unidad,2) -> Liviano | D13: =VLOOKUP(B13,unidad,3) -> FIAT | E13: =VLOOKUP(B13,unidad,4) -> STRADA | F13: =VLOOKUP(B13,unidad,5) -> AH210SR | G13: Cuevas Miguel Hector | H13: Base | I13: 0 | J13: Base | K13: 0.99930556 | N13: 0 | O13: =VLOOKUP(N13,estado,3) -> Seleccione Estado
A14: =+A13+1 -> 10 | B14: GDU065 | C14: =VLOOKUP(B14,unidad,2) -> Liviano | D14: =VLOOKUP(B14,unidad,3) -> FIAT | E14: =VLOOKUP(B14,unidad,4) -> FIORINO | F14: =VLOOKUP(B14,unidad,5) -> AH255OH | H14: Base | J14: Base | N14: 0 | O14: =VLOOKUP(N14,estado,3) -> Seleccione Estado
A15: =+A14+1 -> 11 | B15: GDU063 | C15: =VLOOKUP(B15,unidad,2) -> Liviano | D15: =VLOOKUP(B15,unidad,3) -> TOYOTA | E15: =VLOOKUP(B15,unidad,4) -> HILUX | F15: =VLOOKUP(B15,unidad,5) -> AD761JW | G15: Bordones Requena Jordan | H15: Base | I15: 0 | J15: Base | K15: 0.99930556 | N15: 0 | O15: =VLOOKUP(N15,estado,3) -> Seleccione Estado
A16: =+A15+1 -> 12 | B16: GDU061 | C16: =VLOOKUP(B16,unidad,2) -> Liviano | D16: RENAULT | E16: KANGOO | F16: AF677IV | H16: Base | J16: Base | N16: 0 | O16: =VLOOKUP(N16,estado,3) -> Seleccione Estado
A17: =+A16+1 -> 13 | B17: GDU064 | C17: =VLOOKUP(B17,unidad,2) -> Liviano | D17: =VLOOKUP(B17,unidad,3) -> FIAT | E17: =VLOOKUP(B17,unidad,4) -> STRADA | F17: =VLOOKUP(B17,unidad,5) -> AH210SR | H17: Base | J17: Base | N17: 0 | O17: =VLOOKUP(N17,estado,3) -> Seleccione Estado
A18: =+A17+1 -> 14 | B18: GDU000 | C18: =VLOOKUP(B18,unidad,2) -> Selecciona Equipo | D18: =VLOOKUP(B18,unidad,3) -> 0 | E18: =VLOOKUP(B18,unidad,4) -> 0 | F18: =VLOOKUP(B18,unidad,5) -> 0 | H18: Base | J18: Base | N18: 0 | O18: =VLOOKUP(N18,estado,3) -> Seleccione Estado
A19: =+A18+1 -> 15 | B19: GDU000 | C19: =VLOOKUP(B19,unidad,2) -> Selecciona Equipo | D19: =VLOOKUP(B19,unidad,3) -> 0 | E19: =VLOOKUP(B19,unidad,4) -> 0 | F19: =VLOOKUP(B19,unidad,5) -> 0 | H19: Base | J19: Base | N19: 0 | O19: =VLOOKUP(N19,estado,3) -> Seleccione Estado
A20: =+A19+1 -> 16 | B20: GDU000 | C20: =VLOOKUP(B20,unidad,2) -> Selecciona Equipo | D20: =VLOOKUP(B20,unidad,3) -> 0 | E20: =VLOOKUP(B20,unidad,4) -> 0 | F20: =VLOOKUP(B20,unidad,5) -> 0 | H20: Base | J20: Base | N20: 0 | O20: =VLOOKUP(N20,estado,3) -> Seleccione Estado

Sheet Dia (10)
B1: Asignacion y uso de Vehiculos Livianos
B2: FECHA | D2: ='Dia (1)'!D2+_xlfn.SHEET()-1 -> 46275
H3: Salida | J3: Llegada
B4: Interno | D4: Tipo | E4: Marca | F4: Modelo | G4: Personal Asignado | H4: Lugar | I4: Horario | J4: Lugar | K4: Horario | L4: Uso | M4: Observaciones | N4: Estado
A5: 1 | B5: GDU001 | C5: =VLOOKUP(B5,unidad,2) -> Liviano | D5: =VLOOKUP(B5,unidad,3) -> FIAT | E5: =VLOOKUP(B5,unidad,4) -> UNO | F5: =VLOOKUP(B5,unidad,5) -> EYI 197 | G5: Salvo Jonathan Nicolas | H5: Base | I5: 0 | J5: Base | K5: 0.99930556 | N5: 0 | O5: =VLOOKUP(N5,estado,3) -> Seleccione Estado
A6: =+A5+1 -> 2 | B6: GDU002 | C6: =VLOOKUP(B6,unidad,2) -> Liviano | D6: =VLOOKUP(B6,unidad,3) -> FIAT | E6: =VLOOKUP(B6,unidad,4) -> UNO | F6: =VLOOKUP(B6,unidad,5) -> ODQ 087 | G6: Nappi Kevin Ezequiel | H6: Base | I6: 0.29166667 | J6: Base | K6: 0.58333333 | N6: 0 | O6: =VLOOKUP(N6,estado,3) -> Seleccione Estado
A7: =+A6+1 -> 3 | B7: GDU011 | C7: =VLOOKUP(B7,unidad,2) -> Liviano | D7: =VLOOKUP(B7,unidad,3) -> CHEVROLET | E7: =VLOOKUP(B7,unidad,4) -> CELTA | F7: =VLOOKUP(B7,unidad,5) -> MEE 670 | G7: Barreto Braian Jose | H7: Base | I7: 0 | J7: Base | K7: 0.99930556 | N7: 0 | O7: =VLOOKUP(N7,estado,3) -> Seleccione Estado
A8: =+A7+1 -> 4 | B8: GDU053 | C8: =VLOOKUP(B8,unidad,2) -> Liviano | D8: =VLOOKUP(B8,unidad,3) -> FIAT | E8: =VLOOKUP(B8,unidad,4) -> FIORINO | F8: =VLOOKUP(B8,unidad,5) -> MHX 920 | G8: Arocha Sergio Anibal | H8: Base | I8: 0 | J8: Base | K8: 0.99930556 | N8: 0 | O8: =VLOOKUP(N8,estado,3) -> Seleccione Estado
A9: =+A8+1 -> 5 | B9: GDU061 | C9: =VLOOKUP(B9,unidad,2) -> Liviano | D9: =VLOOKUP(B9,unidad,3) -> RENAULT | E9: =VLOOKUP(B9,unidad,4) -> KANGOO | F9: =VLOOKUP(B9,unidad,5) -> AF 677 IV | G9: Vega Jorge Luis | H9: Base | I9: 0 | J9: Base | K9: 0.99930556 | N9: 0 | O9: =VLOOKUP(N9,estado,3) -> Seleccione Estado
A10: =+A9+1 -> 6 | B10: GDU055 | C10: =VLOOKUP(B10,unidad,2) -> Liviano | D10: =VLOOKUP(B10,unidad,3) -> VOLKSWAGEN | E10: =VLOOKUP(B10,unidad,4) -> AMAROK | F10: =VLOOKUP(B10,unidad,5) -> OGZ 054 | G10: Hermoso Camacho Roberto Rafael | H10: Base | I10: 0.25 | J10: Base | K10: 0.625 | N10: 0 | O10: =VLOOKUP(N10,estado,3) -> Seleccione Estado
A11: =+A10+1 -> 7 | B11: GDU056 | C11: =VLOOKUP(B11,unidad,2) -> Liviano | D11: =VLOOKUP(B11,unidad,3) -> VOLKSWAGEN | E11: =VLOOKUP(B11,unidad,4) -> AMAROK | F11: =VLOOKUP(B11,unidad,5) -> AA 087 LA | G11: Vazquez David Gabriel | H11: Base | I11: 0 | J11: Base | K11: 0.99930556 | N11: 0 | O11: =VLOOKUP(N11,estado,3) -> Seleccione Estado
A12: =+A11+1 -> 8 | B12: GDU057 | C12: =VLOOKUP(B12,unidad,2) -> Liviano | D12: =VLOOKUP(B12,unidad,3) -> VOLKSWAGEN | E12: =VLOOKUP(B12,unidad,4) -> AMAROK | F12: =VLOOKUP(B12,unidad,5) -> NZF 438 | G12: Gonzalez Molinas Juan Alberto | H12: Base | I12: 0 | J12: Base | K12: 0.99930556 | N12: 0 | O12: =VLOOKUP(N12,estado,3) -> Seleccione Estado
A13: =+A12+1 -> 9 | B13: GDU064 | C13: =VLOOKUP(B13,unidad,2) -> Liviano | D13: =VLOOKUP(B13,unidad,3) -> FIAT | E13: =VLOOKUP(B13,unidad,4) -> STRADA | F13: =VLOOKUP(B13,unidad,5) -> AH210SR | G13: Cuevas Miguel Hector | H13: Base | I13: 0 | J13: Base | K13: 0.99930556 | N13: 0 | O13: =VLOOKUP(N13,estado,3) -> Seleccione Estado
A14: =+A13+1 -> 10 | B14: GDU065 | C14: =VLOOKUP(B14,unidad,2) -> Liviano | D14: =VLOOKUP(B14,unidad,3) -> FIAT | E14: =VLOOKUP(B14,unidad,4) -> FIORINO | F14: =VLOOKUP(B14,unidad,5) -> AH255OH | H14: Base | J14: Base | N14: 0 | O14: =VLOOKUP(N14,estado,3) -> Seleccione Estado
A15: =+A14+1 -> 11 | B15: GDU063 | C15: =VLOOKUP(B15,unidad,2) -> Liviano | D15: =VLOOKUP(B15,unidad,3) -> TOYOTA | E15: =VLOOKUP(B15,unidad,4) -> HILUX | F15: =VLOOKUP(B15,unidad,5) -> AD761JW | G15: Barrionuevo Claudio Andres | H15: Base | I15: 0 | J15: Base | K15: 0.99930556 | N15: 0 | O15: =VLOOKUP(N15,estado,3) -> Seleccione Estado
A16: =+A15+1 -> 12 | B16: GDU061 | C16: =VLOOKUP(B16,unidad,2) -> Liviano | D16: RENAULT | E16: KANGOO | F16: AF677IV | H16: Base | J16: Base | N16: 0 | O16: =VLOOKUP(N16,estado,3) -> Seleccione Estado
A17: =+A16+1 -> 13 | B17: GDU064 | C17: =VLOOKUP(B17,unidad,2) -> Liviano | D17: =VLOOKUP(B17,unidad,3) -> FIAT | E17: =VLOOKUP(B17,unidad,4) -> STRADA | F17: =VLOOKUP(B17,unidad,5) -> AH210SR | H17: Base | J17: Base | N17: 0 | O17: =VLOOKUP(N17,estado,3) -> Seleccione Estado
A18: =+A17+1 -> 14 | B18: GDU000 | C18: =VLOOKUP(B18,unidad,2) -> Selecciona Equipo | D18: =VLOOKUP(B18,unidad,3) -> 0 | E18: =VLOOKUP(B18,unidad,4) -> 0 | F18: =VLOOKUP(B18,unidad,5) -> 0 | H18: Base | J18: Base | N18: 0 | O18: =VLOOKUP(N18,estado,3) -> Seleccione Estado
A19: =+A18+1 -> 15 | B19: GDU000 | C19: =VLOOKUP(B19,unidad,2) -> Selecciona Equipo | D19: =VLOOKUP(B19,unidad,3) -> 0 | E19: =VLOOKUP(B19,unidad,4) -> 0 | F19: =VLOOKUP(B19,unidad,5) -> 0 | H19: Base | J19: Base | N19: 0 | O19: =VLOOKUP(N19,estado,3) -> Seleccione Estado
A20: =+A19+1 -> 16 | B20: GDU000 | C20: =VLOOKUP(B20,unidad,2) -> Selecciona Equipo | D20: =VLOOKUP(B20,unidad,3) -> 0 | E20: =VLOOKUP(B20,unidad,4) -> 0 | F20: =VLOOKUP(B20,unidad,5) -> 0 | H20: Base | J20: Base | N20: 0 | O20: =VLOOKUP(N20,estado,3) -> Seleccione Estado

Sheet Dia (11)
B1: Asignacion y uso de Vehiculos Livianos
B2: FECHA | D2: ='Dia (1)'!D2+_xlfn.SHEET()-1 -> 46276
H3: Salida | J3: Llegada
B4: Interno | D4: Tipo | E4: Marca | F4: Modelo | G4: Personal Asignado | H4: Lugar | I4: Horario | J4: Lugar | K4: Horario | L4: Uso | M4: Observaciones | N4: Estado
A5: 1 | B5: GDU001 | C5: =VLOOKUP(B5,unidad,2) -> Liviano | D5: =VLOOKUP(B5,unidad,3) -> FIAT | E5: =VLOOKUP(B5,unidad,4) -> UNO | F5: =VLOOKUP(B5,unidad,5) -> EYI 197 | H5: Base | J5: Base | N5: 0 | O5: =VLOOKUP(N5,estado,3) -> Seleccione Estado
A6: =+A5+1 -> 2 | B6: GDU002 | C6: =VLOOKUP(B6,unidad,2) -> Liviano | D6: =VLOOKUP(B6,unidad,3) -> FIAT | E6: =VLOOKUP(B6,unidad,4) -> UNO | F6: =VLOOKUP(B6,unidad,5) -> ODQ 087 | H6: Base | J6: Base | N6: 0 | O6: =VLOOKUP(N6,estado,3) -> Seleccione Estado
A7: =+A6+1 -> 3 | B7: GDU011 | C7: =VLOOKUP(B7,unidad,2) -> Liviano | D7: =VLOOKUP(B7,unidad,3) -> CHEVROLET | E7: =VLOOKUP(B7,unidad,4) -> CELTA | F7: =VLOOKUP(B7,unidad,5) -> MEE 670 | H7: Base | J7: Base | N7: 0 | O7: =VLOOKUP(N7,estado,3) -> Seleccione Estado
A8: =+A7+1 -> 4 | B8: GDU053 | C8: =VLOOKUP(B8,unidad,2) -> Liviano | D8: =VLOOKUP(B8,unidad,3) -> FIAT | E8: =VLOOKUP(B8,unidad,4) -> FIORINO | F8: =VLOOKUP(B8,unidad,5) -> MHX 920 | H8: Base | J8: Base | N8: 0 | O8: =VLOOKUP(N8,estado,3) -> Seleccione Estado
A9: =+A8+1 -> 5 | B9: GDU061 | C9: =VLOOKUP(B9,unidad,2) -> Liviano | D9: =VLOOKUP(B9,unidad,3) -> RENAULT | E9: =VLOOKUP(B9,unidad,4) -> KANGOO | F9: =VLOOKUP(B9,unidad,5) -> AF 677 IV | H9: Base | J9: Base | N9: 0 | O9: =VLOOKUP(N9,estado,3) -> Seleccione Estado
A10: =+A9+1 -> 6 | B10: GDU055 | C10: =VLOOKUP(B10,unidad,2) -> Liviano | D10: =VLOOKUP(B10,unidad,3) -> VOLKSWAGEN | E10: =VLOOKUP(B10,unidad,4) -> AMAROK | F10: =VLOOKUP(B10,unidad,5) -> OGZ 054 | H10: Base | J10: Base | N10: 0 | O10: =VLOOKUP(N10,estado,3) -> Seleccione Estado
A11: =+A10+1 -> 7 | B11: GDU056 | C11: =VLOOKUP(B11,unidad,2) -> Liviano | D11: =VLOOKUP(B11,unidad,3) -> VOLKSWAGEN | E11: =VLOOKUP(B11,unidad,4) -> AMAROK | F11: =VLOOKUP(B11,unidad,5) -> AA 087 LA | H11: Base | J11: Base | N11: 0 | O11: =VLOOKUP(N11,estado,3) -> Seleccione Estado
A12: =+A11+1 -> 8 | B12: GDU057 | C12: =VLOOKUP(B12,unidad,2) -> Liviano | D12: =VLOOKUP(B12,unidad,3) -> VOLKSWAGEN | E12: =VLOOKUP(B12,unidad,4) -> AMAROK | F12: =VLOOKUP(B12,unidad,5) -> NZF 438 | H12: Base | J12: Base | N12: 0 | O12: =VLOOKUP(N12,estado,3) -> Seleccione Estado
A13: =+A12+1 -> 9 | B13: GDU064 | C13: =VLOOKUP(B13,unidad,2) -> Liviano | D13: =VLOOKUP(B13,unidad,3) -> FIAT | E13: =VLOOKUP(B13,unidad,4) -> STRADA | F13: =VLOOKUP(B13,unidad,5) -> AH210SR | H13: Base | J13: Base | N13: 0 | O13: =VLOOKUP(N13,estado,3) -> Seleccione Estado
A14: =+A13+1 -> 10 | B14: GDU065 | C14: =VLOOKUP(B14,unidad,2) -> Liviano | D14: =VLOOKUP(B14,unidad,3) -> FIAT | E14: =VLOOKUP(B14,unidad,4) -> FIORINO | F14: =VLOOKUP(B14,unidad,5) -> AH255OH | H14: Base | J14: Base | N14: 0 | O14: =VLOOKUP(N14,estado,3) -> Seleccione Estado
A15: =+A14+1 -> 11 | B15: GDU063 | C15: =VLOOKUP(B15,unidad,2) -> Liviano | D15: =VLOOKUP(B15,unidad,3) -> TOYOTA | E15: =VLOOKUP(B15,unidad,4) -> HILUX | F15: =VLOOKUP(B15,unidad,5) -> AD761JW | H15: Base | J15: Base | N15: 0 | O15: =VLOOKUP(N15,estado,3) -> Seleccione Estado
A16: =+A15+1 -> 12 | B16: GDU061 | C16: =VLOOKUP(B16,unidad,2) -> Liviano | D16: RENAULT | E16: KANGOO | F16: AF677IV | H16: Base | J16: Base | N16: 0 | O16: =VLOOKUP(N16,estado,3) -> Seleccione Estado
A17: =+A16+1 -> 13 | B17: GDU064 | C17: =VLOOKUP(B17,unidad,2) -> Liviano | D17: =VLOOKUP(B17,unidad,3) -> FIAT | E17: =VLOOKUP(B17,unidad,4) -> STRADA | F17: =VLOOKUP(B17,unidad,5) -> AH210SR | H17: Base | J17: Base | N17: 0 | O17: =VLOOKUP(N17,estado,3) -> Seleccione Estado
A18: =+A17+1 -> 14 | B18: GDU000 | C18: =VLOOKUP(B18,unidad,2) -> Selecciona Equipo | D18: =VLOOKUP(B18,unidad,3) -> 0 | E18: =VLOOKUP(B18,unidad,4) -> 0 | F18: =VLOOKUP(B18,unidad,5) -> 0 | H18: Base | J18: Base | N18: 0 | O18: =VLOOKUP(N18,estado,3) -> Seleccione Estado
A19: =+A18+1 -> 15 | B19: GDU000 | C19: =VLOOKUP(B19,unidad,2) -> Selecciona Equipo | D19: =VLOOKUP(B19,unidad,3) -> 0 | E19: =VLOOKUP(B19,unidad,4) -> 0 | F19: =VLOOKUP(B19,unidad,5) -> 0 | H19: Base | J19: Base | N19: 0 | O19: =VLOOKUP(N19,estado,3) -> Seleccione Estado
A20: =+A19+1 -> 16 | B20: GDU000 | C20: =VLOOKUP(B20,unidad,2) -> Selecciona Equipo | D20: =VLOOKUP(B20,unidad,3) -> 0 | E20: =VLOOKUP(B20,unidad,4) -> 0 | F20: =VLOOKUP(B20,unidad,5) -> 0 | H20: Base | J20: Base | N20: 0 | O20: =VLOOKUP(N20,estado,3) -> Seleccione Estado
A21: =+A20+1 -> 17 | B21: GDU100 | C21: =VLOOKUP(B21,unidad,2) -> Camion | D21: =VLOOKUP(B21,unidad,3) -> KIA | E21: =VLOOKUP(B21,unidad,4) -> K2500 | F21: =VLOOKUP(B21,unidad,5) -> ONT 594 | H21: Base | J21: Base | N21: 0 | O21: =VLOOKUP(N21,estado,3) -> Seleccione Estado

Sheet Dia (12)
B1: Asignacion y uso de Vehiculos Livianos
B2: FECHA | D2: ='Dia (1)'!D2+_xlfn.SHEET()-1 -> 46277
H3: Salida | J3: Llegada
B4: Interno | D4: Tipo | E4: Marca | F4: Modelo | G4: Personal Asignado | H4: Lugar | I4: Horario | J4: Lugar | K4: Horario | L4: Uso | M4: Observaciones | N4: Estado
A5: 1 | B5: GDU001 | C5: =VLOOKUP(B5,unidad,2) -> Liviano | D5: =VLOOKUP(B5,unidad,3) -> FIAT | E5: =VLOOKUP(B5,unidad,4) -> UNO | F5: =VLOOKUP(B5,unidad,5) -> EYI 197 | H5: Base | J5: Base | N5: 0 | O5: =VLOOKUP(N5,estado,3) -> Seleccione Estado
A6: =+A5+1 -> 2 | B6: GDU002 | C6: =VLOOKUP(B6,unidad,2) -> Liviano | D6: =VLOOKUP(B6,unidad,3) -> FIAT | E6: =VLOOKUP(B6,unidad,4) -> UNO | F6: =VLOOKUP(B6,unidad,5) -> ODQ 087 | H6: Base | J6: Base | N6: 0 | O6: =VLOOKUP(N6,estado,3) -> Seleccione Estado
A7: =+A6+1 -> 3 | B7: GDU011 | C7: =VLOOKUP(B7,unidad,2) -> Liviano | D7: =VLOOKUP(B7,unidad,3) -> CHEVROLET | E7: =VLOOKUP(B7,unidad,4) -> CELTA | F7: =VLOOKUP(B7,unidad,5) -> MEE 670 | H7: Base | J7: Base | N7: 0 | O7: =VLOOKUP(N7,estado,3) -> Seleccione Estado
A8: =+A7+1 -> 4 | B8: GDU053 | C8: =VLOOKUP(B8,unidad,2) -> Liviano | D8: =VLOOKUP(B8,unidad,3) -> FIAT | E8: =VLOOKUP(B8,unidad,4) -> FIORINO | F8: =VLOOKUP(B8,unidad,5) -> MHX 920 | H8: Base | J8: Base | N8: 0 | O8: =VLOOKUP(N8,estado,3) -> Seleccione Estado
A9: =+A8+1 -> 5 | B9: GDU061 | C9: =VLOOKUP(B9,unidad,2) -> Liviano | D9: =VLOOKUP(B9,unidad,3) -> RENAULT | E9: =VLOOKUP(B9,unidad,4) -> KANGOO | F9: =VLOOKUP(B9,unidad,5) -> AF 677 IV | H9: Base | J9: Base | N9: 0 | O9: =VLOOKUP(N9,estado,3) -> Seleccione Estado
A10: =+A9+1 -> 6 | B10: GDU055 | C10: =VLOOKUP(B10,unidad,2) -> Liviano | D10: =VLOOKUP(B10,unidad,3) -> VOLKSWAGEN | E10: =VLOOKUP(B10,unidad,4) -> AMAROK | F10: =VLOOKUP(B10,unidad,5) -> OGZ 054 | H10: Base | J10: Base | N10: 0 | O10: =VLOOKUP(N10,estado,3) -> Seleccione Estado
A11: =+A10+1 -> 7 | B11: GDU056 | C11: =VLOOKUP(B11,unidad,2) -> Liviano | D11: =VLOOKUP(B11,unidad,3) -> VOLKSWAGEN | E11: =VLOOKUP(B11,unidad,4) -> AMAROK | F11: =VLOOKUP(B11,unidad,5) -> AA 087 LA | H11: Base | J11: Base | N11: 0 | O11: =VLOOKUP(N11,estado,3) -> Seleccione Estado
A12: =+A11+1 -> 8 | B12: GDU057 | C12: =VLOOKUP(B12,unidad,2) -> Liviano | D12: =VLOOKUP(B12,unidad,3) -> VOLKSWAGEN | E12: =VLOOKUP(B12,unidad,4) -> AMAROK | F12: =VLOOKUP(B12,unidad,5) -> NZF 438 | H12: Base | J12: Base | N12: 0 | O12: =VLOOKUP(N12,estado,3) -> Seleccione Estado
A13: =+A12+1 -> 9 | B13: GDU064 | C13: =VLOOKUP(B13,unidad,2) -> Liviano | D13: =VLOOKUP(B13,unidad,3) -> FIAT | E13: =VLOOKUP(B13,unidad,4) -> STRADA | F13: =VLOOKUP(B13,unidad,5) -> AH210SR | H13: Base | J13: Base | N13: 0 | O13: =VLOOKUP(N13,estado,3) -> Seleccione Estado
A14: =+A13+1 -> 10 | B14: GDU065 | C14: =VLOOKUP(B14,unidad,2) -> Liviano | D14: =VLOOKUP(B14,unidad,3) -> FIAT | E14: =VLOOKUP(B14,unidad,4) -> FIORINO | F14: =VLOOKUP(B14,unidad,5) -> AH255OH | H14: Base | J14: Base | N14: 0 | O14: =VLOOKUP(N14,estado,3) -> Seleccione Estado
A15: =+A14+1 -> 11 | B15: GDU063 | C15: =VLOOKUP(B15,unidad,2) -> Liviano | D15: =VLOOKUP(B15,unidad,3) -> TOYOTA | E15: =VLOOKUP(B15,unidad,4) -> HILUX | F15: =VLOOKUP(B15,unidad,5) -> AD761JW | H15: Base | J15: Base | N15: 0 | O15: =VLOOKUP(N15,estado,3) -> Seleccione Estado
A16: =+A15+1 -> 12 | B16: GDU061 | C16: =VLOOKUP(B16,unidad,2) -> Liviano | D16: RENAULT | E16: KANGOO | F16: AF677IV | H16: Base | J16: Base | N16: 0 | O16: =VLOOKUP(N16,estado,3) -> Seleccione Estado
A17: =+A16+1 -> 13 | B17: GDU064 | C17: =VLOOKUP(B17,unidad,2) -> Liviano | D17: =VLOOKUP(B17,unidad,3) -> FIAT | E17: =VLOOKUP(B17,unidad,4) -> STRADA | F17: =VLOOKUP(B17,unidad,5) -> AH210SR | H17: Base | J17: Base | N17: 0 | O17: =VLOOKUP(N17,estado,3) -> Seleccione Estado
A18: =+A17+1 -> 14 | B18: GDU000 | C18: =VLOOKUP(B18,unidad,2) -> Selecciona Equipo | D18: =VLOOKUP(B18,unidad,3) -> 0 | E18: =VLOOKUP(B18,unidad,4) -> 0 | F18: =VLOOKUP(B18,unidad,5) -> 0 | H18: Base | J18: Base | N18: 0 | O18: =VLOOKUP(N18,estado,3) -> Seleccione Estado
A19: =+A18+1 -> 15 | B19: GDU000 | C19: =VLOOKUP(B19,unidad,2) -> Selecciona Equipo | D19: =VLOOKUP(B19,unidad,3) -> 0 | E19: =VLOOKUP(B19,unidad,4) -> 0 | F19: =VLOOKUP(B19,unidad,5) -> 0 | H19: Base | J19: Base | N19: 0 | O19: =VLOOKUP(N19,estado,3) -> Seleccione Estado
A20: =+A19+1 -> 16 | B20: GDU000 | C20: =VLOOKUP(B20,unidad,2) -> Selecciona Equipo | D20: =VLOOKUP(B20,unidad,3) -> 0 | E20: =VLOOKUP(B20,unidad,4) -> 0 | F20: =VLOOKUP(B20,unidad,5) -> 0 | H20: Base | J20: Base | N20: 0 | O20: =VLOOKUP(N20,estado,3) -> Seleccione Estado

Sheet Dia (13)
B1: Asignacion y uso de Vehiculos Livianos
B2: FECHA | D2: ='Dia (1)'!D2+_xlfn.SHEET()-1 -> 46278
H3: Salida | J3: Llegada
B4: Interno | D4: Tipo | E4: Marca | F4: Modelo | G4: Personal Asignado | H4: Lugar | I4: Horario | J4: Lugar | K4: Horario | L4: Uso | M4: Observaciones | N4: Estado
A5: 1 | B5: GDU001 | C5: =VLOOKUP(B5,unidad,2) -> Liviano | D5: =VLOOKUP(B5,unidad,3) -> FIAT | E5: =VLOOKUP(B5,unidad,4) -> UNO | F5: =VLOOKUP(B5,unidad,5) -> EYI 197 | H5: Base | J5: Base | N5: 0 | O5: =VLOOKUP(N5,estado,3) -> Seleccione Estado
